ERROR:root:http://www.thehindu.com/mailto:web.thehindu@thehindu.co.in
Traceback (most recent call last):
  File "web_search3.py", line 33, in searchUrl
    urlContent = urllib.request.urlopen(req).read()
  File "/usr/local/lib/python3.6/urllib/request.py", line 223, in urlopen
    return opener.open(url, data, timeout)
  File "/usr/local/lib/python3.6/urllib/request.py", line 532, in open
    response = meth(req, response)
  File "/usr/local/lib/python3.6/urllib/request.py", line 642, in http_response
    'http', request, response, code, msg, hdrs)
  File "/usr/local/lib/python3.6/urllib/request.py", line 570, in error
    return self._call_chain(*args)
  File "/usr/local/lib/python3.6/urllib/request.py", line 504, in _call_chain
    result = func(*args)
  File "/usr/local/lib/python3.6/urllib/request.py", line 650, in http_error_default
    raise HTTPError(req.full_url, code, msg, hdrs, fp)
urllib.error.HTTPError: HTTP Error 404: Not Found
ERROR:root:http://www.thehindu.com/javascript:void(0)
Traceback (most recent call last):
  File "web_search3.py", line 33, in searchUrl
    urlContent = urllib.request.urlopen(req).read()
  File "/usr/local/lib/python3.6/urllib/request.py", line 223, in urlopen
    return opener.open(url, data, timeout)
  File "/usr/local/lib/python3.6/urllib/request.py", line 532, in open
    response = meth(req, response)
  File "/usr/local/lib/python3.6/urllib/request.py", line 642, in http_response
    'http', request, response, code, msg, hdrs)
  File "/usr/local/lib/python3.6/urllib/request.py", line 564, in error
    result = self._call_chain(*args)
  File "/usr/local/lib/python3.6/urllib/request.py", line 504, in _call_chain
    result = func(*args)
  File "/usr/local/lib/python3.6/urllib/request.py", line 756, in http_error_302
    return self.parent.open(new, timeout=req.timeout)
  File "/usr/local/lib/python3.6/urllib/request.py", line 532, in open
    response = meth(req, response)
  File "/usr/local/lib/python3.6/urllib/request.py", line 642, in http_response
    'http', request, response, code, msg, hdrs)
  File "/usr/local/lib/python3.6/urllib/request.py", line 570, in error
    return self._call_chain(*args)
  File "/usr/local/lib/python3.6/urllib/request.py", line 504, in _call_chain
    result = func(*args)
  File "/usr/local/lib/python3.6/urllib/request.py", line 650, in http_error_default
    raise HTTPError(req.full_url, code, msg, hdrs, fp)
urllib.error.HTTPError: HTTP Error 404: Not Found
ERROR:root:http://www.newindianexpress.com/javascript:void(0)
Traceback (most recent call last):
  File "web_search3.py", line 33, in searchUrl
    urlContent = urllib.request.urlopen(req).read()
  File "/usr/local/lib/python3.6/urllib/request.py", line 223, in urlopen
    return opener.open(url, data, timeout)
  File "/usr/local/lib/python3.6/urllib/request.py", line 532, in open
    response = meth(req, response)
  File "/usr/local/lib/python3.6/urllib/request.py", line 642, in http_response
    'http', request, response, code, msg, hdrs)
  File "/usr/local/lib/python3.6/urllib/request.py", line 570, in error
    return self._call_chain(*args)
  File "/usr/local/lib/python3.6/urllib/request.py", line 504, in _call_chain
    result = func(*args)
  File "/usr/local/lib/python3.6/urllib/request.py", line 650, in http_error_default
    raise HTTPError(req.full_url, code, msg, hdrs, fp)
urllib.error.HTTPError: HTTP Error 400: Bad Request
ERROR:root:http://timesofindia.indiatimes.com/javascript:void(0)
Traceback (most recent call last):
  File "web_search3.py", line 33, in searchUrl
    urlContent = urllib.request.urlopen(req).read()
  File "/usr/local/lib/python3.6/urllib/request.py", line 223, in urlopen
    return opener.open(url, data, timeout)
  File "/usr/local/lib/python3.6/urllib/request.py", line 532, in open
    response = meth(req, response)
  File "/usr/local/lib/python3.6/urllib/request.py", line 642, in http_response
    'http', request, response, code, msg, hdrs)
  File "/usr/local/lib/python3.6/urllib/request.py", line 570, in error
    return self._call_chain(*args)
  File "/usr/local/lib/python3.6/urllib/request.py", line 504, in _call_chain
    result = func(*args)
  File "/usr/local/lib/python3.6/urllib/request.py", line 650, in http_error_default
    raise HTTPError(req.full_url, code, msg, hdrs, fp)
urllib.error.HTTPError: HTTP Error 404: Not Found
ERROR:root:http://timesofindia.indiatimes.com/javascript:void(0)
Traceback (most recent call last):
  File "web_search3.py", line 33, in searchUrl
    urlContent = urllib.request.urlopen(req).read()
  File "/usr/local/lib/python3.6/urllib/request.py", line 223, in urlopen
    return opener.open(url, data, timeout)
  File "/usr/local/lib/python3.6/urllib/request.py", line 532, in open
    response = meth(req, response)
  File "/usr/local/lib/python3.6/urllib/request.py", line 642, in http_response
    'http', request, response, code, msg, hdrs)
  File "/usr/local/lib/python3.6/urllib/request.py", line 570, in error
    return self._call_chain(*args)
  File "/usr/local/lib/python3.6/urllib/request.py", line 504, in _call_chain
    result = func(*args)
  File "/usr/local/lib/python3.6/urllib/request.py", line 650, in http_error_default
    raise HTTPError(req.full_url, code, msg, hdrs, fp)
urllib.error.HTTPError: HTTP Error 404: Not Found
ERROR:root:http://zeenews.india.com/javascript:void(0)
Traceback (most recent call last):
  File "web_search3.py", line 33, in searchUrl
    urlContent = urllib.request.urlopen(req).read()
  File "/usr/local/lib/python3.6/urllib/request.py", line 223, in urlopen
    return opener.open(url, data, timeout)
  File "/usr/local/lib/python3.6/urllib/request.py", line 532, in open
    response = meth(req, response)
  File "/usr/local/lib/python3.6/urllib/request.py", line 642, in http_response
    'http', request, response, code, msg, hdrs)
  File "/usr/local/lib/python3.6/urllib/request.py", line 570, in error
    return self._call_chain(*args)
  File "/usr/local/lib/python3.6/urllib/request.py", line 504, in _call_chain
    result = func(*args)
  File "/usr/local/lib/python3.6/urllib/request.py", line 650, in http_error_default
    raise HTTPError(req.full_url, code, msg, hdrs, fp)
urllib.error.HTTPError: HTTP Error 404: Not Found
ERROR:root:http://zeenews.india.com/sports target=
Traceback (most recent call last):
  File "web_search3.py", line 33, in searchUrl
    urlContent = urllib.request.urlopen(req).read()
  File "/usr/local/lib/python3.6/urllib/request.py", line 223, in urlopen
    return opener.open(url, data, timeout)
  File "/usr/local/lib/python3.6/urllib/request.py", line 532, in open
    response = meth(req, response)
  File "/usr/local/lib/python3.6/urllib/request.py", line 642, in http_response
    'http', request, response, code, msg, hdrs)
  File "/usr/local/lib/python3.6/urllib/request.py", line 570, in error
    return self._call_chain(*args)
  File "/usr/local/lib/python3.6/urllib/request.py", line 504, in _call_chain
    result = func(*args)
  File "/usr/local/lib/python3.6/urllib/request.py", line 650, in http_error_default
    raise HTTPError(req.full_url, code, msg, hdrs, fp)
urllib.error.HTTPError: HTTP Error 400: Bad Request
ERROR:root:http://zeenews.india.com/hindi/news/category/देश
Traceback (most recent call last):
  File "web_search3.py", line 33, in searchUrl
    urlContent = urllib.request.urlopen(req).read()
  File "/usr/local/lib/python3.6/urllib/request.py", line 223, in urlopen
    return opener.open(url, data, timeout)
  File "/usr/local/lib/python3.6/urllib/request.py", line 526, in open
    response = self._open(req, data)
  File "/usr/local/lib/python3.6/urllib/request.py", line 544, in _open
    '_open', req)
  File "/usr/local/lib/python3.6/urllib/request.py", line 504, in _call_chain
    result = func(*args)
  File "/usr/local/lib/python3.6/urllib/request.py", line 1346, in http_open
    return self.do_open(http.client.HTTPConnection, req)
  File "/usr/local/lib/python3.6/urllib/request.py", line 1318, in do_open
    encode_chunked=req.has_header('Transfer-encoding'))
  File "/usr/local/lib/python3.6/http/client.py", line 1239, in request
    self._send_request(method, url, body, headers, encode_chunked)
  File "/usr/local/lib/python3.6/http/client.py", line 1250, in _send_request
    self.putrequest(method, url, **skips)
  File "/usr/local/lib/python3.6/http/client.py", line 1117, in putrequest
    self._output(request.encode('ascii'))
UnicodeEncodeError: 'ascii' codec can't encode characters in position 25-27: ordinal not in range(128)
ERROR:root:http://zeenews.india.com/hindi/news/category/प्रदेश
Traceback (most recent call last):
  File "web_search3.py", line 33, in searchUrl
    urlContent = urllib.request.urlopen(req).read()
  File "/usr/local/lib/python3.6/urllib/request.py", line 223, in urlopen
    return opener.open(url, data, timeout)
  File "/usr/local/lib/python3.6/urllib/request.py", line 526, in open
    response = self._open(req, data)
  File "/usr/local/lib/python3.6/urllib/request.py", line 544, in _open
    '_open', req)
  File "/usr/local/lib/python3.6/urllib/request.py", line 504, in _call_chain
    result = func(*args)
  File "/usr/local/lib/python3.6/urllib/request.py", line 1346, in http_open
    return self.do_open(http.client.HTTPConnection, req)
  File "/usr/local/lib/python3.6/urllib/request.py", line 1318, in do_open
    encode_chunked=req.has_header('Transfer-encoding'))
  File "/usr/local/lib/python3.6/http/client.py", line 1239, in request
    self._send_request(method, url, body, headers, encode_chunked)
  File "/usr/local/lib/python3.6/http/client.py", line 1250, in _send_request
    self.putrequest(method, url, **skips)
  File "/usr/local/lib/python3.6/http/client.py", line 1117, in putrequest
    self._output(request.encode('ascii'))
UnicodeEncodeError: 'ascii' codec can't encode characters in position 25-30: ordinal not in range(128)
ERROR:root:http://zeenews.india.com/hindi/news/category/दुनिया
Traceback (most recent call last):
  File "web_search3.py", line 33, in searchUrl
    urlContent = urllib.request.urlopen(req).read()
  File "/usr/local/lib/python3.6/urllib/request.py", line 223, in urlopen
    return opener.open(url, data, timeout)
  File "/usr/local/lib/python3.6/urllib/request.py", line 526, in open
    response = self._open(req, data)
  File "/usr/local/lib/python3.6/urllib/request.py", line 544, in _open
    '_open', req)
  File "/usr/local/lib/python3.6/urllib/request.py", line 504, in _call_chain
    result = func(*args)
  File "/usr/local/lib/python3.6/urllib/request.py", line 1346, in http_open
    return self.do_open(http.client.HTTPConnection, req)
  File "/usr/local/lib/python3.6/urllib/request.py", line 1318, in do_open
    encode_chunked=req.has_header('Transfer-encoding'))
  File "/usr/local/lib/python3.6/http/client.py", line 1239, in request
    self._send_request(method, url, body, headers, encode_chunked)
  File "/usr/local/lib/python3.6/http/client.py", line 1250, in _send_request
    self.putrequest(method, url, **skips)
  File "/usr/local/lib/python3.6/http/client.py", line 1117, in putrequest
    self._output(request.encode('ascii'))
UnicodeEncodeError: 'ascii' codec can't encode characters in position 25-30: ordinal not in range(128)
ERROR:root:http://zeenews.india.com/hindi/news/category/खेल-खिलाड़ी
Traceback (most recent call last):
  File "web_search3.py", line 33, in searchUrl
    urlContent = urllib.request.urlopen(req).read()
  File "/usr/local/lib/python3.6/urllib/request.py", line 223, in urlopen
    return opener.open(url, data, timeout)
  File "/usr/local/lib/python3.6/urllib/request.py", line 526, in open
    response = self._open(req, data)
  File "/usr/local/lib/python3.6/urllib/request.py", line 544, in _open
    '_open', req)
  File "/usr/local/lib/python3.6/urllib/request.py", line 504, in _call_chain
    result = func(*args)
  File "/usr/local/lib/python3.6/urllib/request.py", line 1346, in http_open
    return self.do_open(http.client.HTTPConnection, req)
  File "/usr/local/lib/python3.6/urllib/request.py", line 1318, in do_open
    encode_chunked=req.has_header('Transfer-encoding'))
  File "/usr/local/lib/python3.6/http/client.py", line 1239, in request
    self._send_request(method, url, body, headers, encode_chunked)
  File "/usr/local/lib/python3.6/http/client.py", line 1250, in _send_request
    self.putrequest(method, url, **skips)
  File "/usr/local/lib/python3.6/http/client.py", line 1117, in putrequest
    self._output(request.encode('ascii'))
UnicodeEncodeError: 'ascii' codec can't encode characters in position 25-27: ordinal not in range(128)
ERROR:root:http://zeenews.india.com/hindi/news/category/कारोबार
Traceback (most recent call last):
  File "web_search3.py", line 33, in searchUrl
    urlContent = urllib.request.urlopen(req).read()
  File "/usr/local/lib/python3.6/urllib/request.py", line 223, in urlopen
    return opener.open(url, data, timeout)
  File "/usr/local/lib/python3.6/urllib/request.py", line 526, in open
    response = self._open(req, data)
  File "/usr/local/lib/python3.6/urllib/request.py", line 544, in _open
    '_open', req)
  File "/usr/local/lib/python3.6/urllib/request.py", line 504, in _call_chain
    result = func(*args)
  File "/usr/local/lib/python3.6/urllib/request.py", line 1346, in http_open
    return self.do_open(http.client.HTTPConnection, req)
  File "/usr/local/lib/python3.6/urllib/request.py", line 1318, in do_open
    encode_chunked=req.has_header('Transfer-encoding'))
  File "/usr/local/lib/python3.6/http/client.py", line 1239, in request
    self._send_request(method, url, body, headers, encode_chunked)
  File "/usr/local/lib/python3.6/http/client.py", line 1250, in _send_request
    self.putrequest(method, url, **skips)
  File "/usr/local/lib/python3.6/http/client.py", line 1117, in putrequest
    self._output(request.encode('ascii'))
UnicodeEncodeError: 'ascii' codec can't encode characters in position 25-31: ordinal not in range(128)
ERROR:root:http://zeenews.india.com/hindi/news/category/ज्ञान-विज्ञान
Traceback (most recent call last):
  File "web_search3.py", line 33, in searchUrl
    urlContent = urllib.request.urlopen(req).read()
  File "/usr/local/lib/python3.6/urllib/request.py", line 223, in urlopen
    return opener.open(url, data, timeout)
  File "/usr/local/lib/python3.6/urllib/request.py", line 526, in open
    response = self._open(req, data)
  File "/usr/local/lib/python3.6/urllib/request.py", line 544, in _open
    '_open', req)
  File "/usr/local/lib/python3.6/urllib/request.py", line 504, in _call_chain
    result = func(*args)
  File "/usr/local/lib/python3.6/urllib/request.py", line 1346, in http_open
    return self.do_open(http.client.HTTPConnection, req)
  File "/usr/local/lib/python3.6/urllib/request.py", line 1318, in do_open
    encode_chunked=req.has_header('Transfer-encoding'))
  File "/usr/local/lib/python3.6/http/client.py", line 1239, in request
    self._send_request(method, url, body, headers, encode_chunked)
  File "/usr/local/lib/python3.6/http/client.py", line 1250, in _send_request
    self.putrequest(method, url, **skips)
  File "/usr/local/lib/python3.6/http/client.py", line 1117, in putrequest
    self._output(request.encode('ascii'))
UnicodeEncodeError: 'ascii' codec can't encode characters in position 25-29: ordinal not in range(128)
ERROR:root:http://zeenews.india.com/hindi/news/category/मनोरंजन
Traceback (most recent call last):
  File "web_search3.py", line 33, in searchUrl
    urlContent = urllib.request.urlopen(req).read()
  File "/usr/local/lib/python3.6/urllib/request.py", line 223, in urlopen
    return opener.open(url, data, timeout)
  File "/usr/local/lib/python3.6/urllib/request.py", line 526, in open
    response = self._open(req, data)
  File "/usr/local/lib/python3.6/urllib/request.py", line 544, in _open
    '_open', req)
  File "/usr/local/lib/python3.6/urllib/request.py", line 504, in _call_chain
    result = func(*args)
  File "/usr/local/lib/python3.6/urllib/request.py", line 1346, in http_open
    return self.do_open(http.client.HTTPConnection, req)
  File "/usr/local/lib/python3.6/urllib/request.py", line 1318, in do_open
    encode_chunked=req.has_header('Transfer-encoding'))
  File "/usr/local/lib/python3.6/http/client.py", line 1239, in request
    self._send_request(method, url, body, headers, encode_chunked)
  File "/usr/local/lib/python3.6/http/client.py", line 1250, in _send_request
    self.putrequest(method, url, **skips)
  File "/usr/local/lib/python3.6/http/client.py", line 1117, in putrequest
    self._output(request.encode('ascii'))
UnicodeEncodeError: 'ascii' codec can't encode characters in position 25-31: ordinal not in range(128)
ERROR:root:http://zeenews.india.com/hindi/news/category/ज़ी-स्पेशल
Traceback (most recent call last):
  File "web_search3.py", line 33, in searchUrl
    urlContent = urllib.request.urlopen(req).read()
  File "/usr/local/lib/python3.6/urllib/request.py", line 223, in urlopen
    return opener.open(url, data, timeout)
  File "/usr/local/lib/python3.6/urllib/request.py", line 526, in open
    response = self._open(req, data)
  File "/usr/local/lib/python3.6/urllib/request.py", line 544, in _open
    '_open', req)
  File "/usr/local/lib/python3.6/urllib/request.py", line 504, in _call_chain
    result = func(*args)
  File "/usr/local/lib/python3.6/urllib/request.py", line 1346, in http_open
    return self.do_open(http.client.HTTPConnection, req)
  File "/usr/local/lib/python3.6/urllib/request.py", line 1318, in do_open
    encode_chunked=req.has_header('Transfer-encoding'))
  File "/usr/local/lib/python3.6/http/client.py", line 1239, in request
    self._send_request(method, url, body, headers, encode_chunked)
  File "/usr/local/lib/python3.6/http/client.py", line 1250, in _send_request
    self.putrequest(method, url, **skips)
  File "/usr/local/lib/python3.6/http/client.py", line 1117, in putrequest
    self._output(request.encode('ascii'))
UnicodeEncodeError: 'ascii' codec can't encode characters in position 25-27: ordinal not in range(128)
ERROR:root:http://zeenews.india.com/hindi/news/category/सेहत
Traceback (most recent call last):
  File "web_search3.py", line 33, in searchUrl
    urlContent = urllib.request.urlopen(req).read()
  File "/usr/local/lib/python3.6/urllib/request.py", line 223, in urlopen
    return opener.open(url, data, timeout)
  File "/usr/local/lib/python3.6/urllib/request.py", line 526, in open
    response = self._open(req, data)
  File "/usr/local/lib/python3.6/urllib/request.py", line 544, in _open
    '_open', req)
  File "/usr/local/lib/python3.6/urllib/request.py", line 504, in _call_chain
    result = func(*args)
  File "/usr/local/lib/python3.6/urllib/request.py", line 1346, in http_open
    return self.do_open(http.client.HTTPConnection, req)
  File "/usr/local/lib/python3.6/urllib/request.py", line 1318, in do_open
    encode_chunked=req.has_header('Transfer-encoding'))
  File "/usr/local/lib/python3.6/http/client.py", line 1239, in request
    self._send_request(method, url, body, headers, encode_chunked)
  File "/usr/local/lib/python3.6/http/client.py", line 1250, in _send_request
    self.putrequest(method, url, **skips)
  File "/usr/local/lib/python3.6/http/client.py", line 1117, in putrequest
    self._output(request.encode('ascii'))
UnicodeEncodeError: 'ascii' codec can't encode characters in position 25-28: ordinal not in range(128)
ERROR:root:http://zeenews.india.com/marathi/news/category/मुंबई
Traceback (most recent call last):
  File "web_search3.py", line 33, in searchUrl
    urlContent = urllib.request.urlopen(req).read()
  File "/usr/local/lib/python3.6/urllib/request.py", line 223, in urlopen
    return opener.open(url, data, timeout)
  File "/usr/local/lib/python3.6/urllib/request.py", line 526, in open
    response = self._open(req, data)
  File "/usr/local/lib/python3.6/urllib/request.py", line 544, in _open
    '_open', req)
  File "/usr/local/lib/python3.6/urllib/request.py", line 504, in _call_chain
    result = func(*args)
  File "/usr/local/lib/python3.6/urllib/request.py", line 1346, in http_open
    return self.do_open(http.client.HTTPConnection, req)
  File "/usr/local/lib/python3.6/urllib/request.py", line 1318, in do_open
    encode_chunked=req.has_header('Transfer-encoding'))
  File "/usr/local/lib/python3.6/http/client.py", line 1239, in request
    self._send_request(method, url, body, headers, encode_chunked)
  File "/usr/local/lib/python3.6/http/client.py", line 1250, in _send_request
    self.putrequest(method, url, **skips)
  File "/usr/local/lib/python3.6/http/client.py", line 1117, in putrequest
    self._output(request.encode('ascii'))
UnicodeEncodeError: 'ascii' codec can't encode characters in position 27-31: ordinal not in range(128)
ERROR:root:http://zeenews.india.com/marathi/news/category/महाराष्ट्र-2
Traceback (most recent call last):
  File "web_search3.py", line 33, in searchUrl
    urlContent = urllib.request.urlopen(req).read()
  File "/usr/local/lib/python3.6/urllib/request.py", line 223, in urlopen
    return opener.open(url, data, timeout)
  File "/usr/local/lib/python3.6/urllib/request.py", line 526, in open
    response = self._open(req, data)
  File "/usr/local/lib/python3.6/urllib/request.py", line 544, in _open
    '_open', req)
  File "/usr/local/lib/python3.6/urllib/request.py", line 504, in _call_chain
    result = func(*args)
  File "/usr/local/lib/python3.6/urllib/request.py", line 1346, in http_open
    return self.do_open(http.client.HTTPConnection, req)
  File "/usr/local/lib/python3.6/urllib/request.py", line 1318, in do_open
    encode_chunked=req.has_header('Transfer-encoding'))
  File "/usr/local/lib/python3.6/http/client.py", line 1239, in request
    self._send_request(method, url, body, headers, encode_chunked)
  File "/usr/local/lib/python3.6/http/client.py", line 1250, in _send_request
    self.putrequest(method, url, **skips)
  File "/usr/local/lib/python3.6/http/client.py", line 1117, in putrequest
    self._output(request.encode('ascii'))
UnicodeEncodeError: 'ascii' codec can't encode characters in position 27-36: ordinal not in range(128)
ERROR:root:http://zeenews.india.com/marathi/news/category/भारत
Traceback (most recent call last):
  File "web_search3.py", line 33, in searchUrl
    urlContent = urllib.request.urlopen(req).read()
  File "/usr/local/lib/python3.6/urllib/request.py", line 223, in urlopen
    return opener.open(url, data, timeout)
  File "/usr/local/lib/python3.6/urllib/request.py", line 526, in open
    response = self._open(req, data)
  File "/usr/local/lib/python3.6/urllib/request.py", line 544, in _open
    '_open', req)
  File "/usr/local/lib/python3.6/urllib/request.py", line 504, in _call_chain
    result = func(*args)
  File "/usr/local/lib/python3.6/urllib/request.py", line 1346, in http_open
    return self.do_open(http.client.HTTPConnection, req)
  File "/usr/local/lib/python3.6/urllib/request.py", line 1318, in do_open
    encode_chunked=req.has_header('Transfer-encoding'))
  File "/usr/local/lib/python3.6/http/client.py", line 1239, in request
    self._send_request(method, url, body, headers, encode_chunked)
  File "/usr/local/lib/python3.6/http/client.py", line 1250, in _send_request
    self.putrequest(method, url, **skips)
  File "/usr/local/lib/python3.6/http/client.py", line 1117, in putrequest
    self._output(request.encode('ascii'))
UnicodeEncodeError: 'ascii' codec can't encode characters in position 27-30: ordinal not in range(128)
ERROR:root:http://zeenews.india.com/marathi/news/category/विश्व
Traceback (most recent call last):
  File "web_search3.py", line 33, in searchUrl
    urlContent = urllib.request.urlopen(req).read()
  File "/usr/local/lib/python3.6/urllib/request.py", line 223, in urlopen
    return opener.open(url, data, timeout)
  File "/usr/local/lib/python3.6/urllib/request.py", line 526, in open
    response = self._open(req, data)
  File "/usr/local/lib/python3.6/urllib/request.py", line 544, in _open
    '_open', req)
  File "/usr/local/lib/python3.6/urllib/request.py", line 504, in _call_chain
    result = func(*args)
  File "/usr/local/lib/python3.6/urllib/request.py", line 1346, in http_open
    return self.do_open(http.client.HTTPConnection, req)
  File "/usr/local/lib/python3.6/urllib/request.py", line 1318, in do_open
    encode_chunked=req.has_header('Transfer-encoding'))
  File "/usr/local/lib/python3.6/http/client.py", line 1239, in request
    self._send_request(method, url, body, headers, encode_chunked)
  File "/usr/local/lib/python3.6/http/client.py", line 1250, in _send_request
    self.putrequest(method, url, **skips)
  File "/usr/local/lib/python3.6/http/client.py", line 1117, in putrequest
    self._output(request.encode('ascii'))
UnicodeEncodeError: 'ascii' codec can't encode characters in position 27-31: ordinal not in range(128)
ERROR:root:http://zeenews.india.com/marathi/news/category/स्पोर्ट्स-बार
Traceback (most recent call last):
  File "web_search3.py", line 33, in searchUrl
    urlContent = urllib.request.urlopen(req).read()
  File "/usr/local/lib/python3.6/urllib/request.py", line 223, in urlopen
    return opener.open(url, data, timeout)
  File "/usr/local/lib/python3.6/urllib/request.py", line 526, in open
    response = self._open(req, data)
  File "/usr/local/lib/python3.6/urllib/request.py", line 544, in _open
    '_open', req)
  File "/usr/local/lib/python3.6/urllib/request.py", line 504, in _call_chain
    result = func(*args)
  File "/usr/local/lib/python3.6/urllib/request.py", line 1346, in http_open
    return self.do_open(http.client.HTTPConnection, req)
  File "/usr/local/lib/python3.6/urllib/request.py", line 1318, in do_open
    encode_chunked=req.has_header('Transfer-encoding'))
  File "/usr/local/lib/python3.6/http/client.py", line 1239, in request
    self._send_request(method, url, body, headers, encode_chunked)
  File "/usr/local/lib/python3.6/http/client.py", line 1250, in _send_request
    self.putrequest(method, url, **skips)
  File "/usr/local/lib/python3.6/http/client.py", line 1117, in putrequest
    self._output(request.encode('ascii'))
UnicodeEncodeError: 'ascii' codec can't encode characters in position 27-35: ordinal not in range(128)
ERROR:root:http://zeenews.india.com/marathi/news/category/कल्लाबाजी
Traceback (most recent call last):
  File "web_search3.py", line 33, in searchUrl
    urlContent = urllib.request.urlopen(req).read()
  File "/usr/local/lib/python3.6/urllib/request.py", line 223, in urlopen
    return opener.open(url, data, timeout)
  File "/usr/local/lib/python3.6/urllib/request.py", line 526, in open
    response = self._open(req, data)
  File "/usr/local/lib/python3.6/urllib/request.py", line 544, in _open
    '_open', req)
  File "/usr/local/lib/python3.6/urllib/request.py", line 504, in _call_chain
    result = func(*args)
  File "/usr/local/lib/python3.6/urllib/request.py", line 1346, in http_open
    return self.do_open(http.client.HTTPConnection, req)
  File "/usr/local/lib/python3.6/urllib/request.py", line 1318, in do_open
    encode_chunked=req.has_header('Transfer-encoding'))
  File "/usr/local/lib/python3.6/http/client.py", line 1239, in request
    self._send_request(method, url, body, headers, encode_chunked)
  File "/usr/local/lib/python3.6/http/client.py", line 1250, in _send_request
    self.putrequest(method, url, **skips)
  File "/usr/local/lib/python3.6/http/client.py", line 1117, in putrequest
    self._output(request.encode('ascii'))
UnicodeEncodeError: 'ascii' codec can't encode characters in position 27-35: ordinal not in range(128)
ERROR:root:http://zeenews.india.com/marathi/news/category/राहा-फिट
Traceback (most recent call last):
  File "web_search3.py", line 33, in searchUrl
    urlContent = urllib.request.urlopen(req).read()
  File "/usr/local/lib/python3.6/urllib/request.py", line 223, in urlopen
    return opener.open(url, data, timeout)
  File "/usr/local/lib/python3.6/urllib/request.py", line 526, in open
    response = self._open(req, data)
  File "/usr/local/lib/python3.6/urllib/request.py", line 544, in _open
    '_open', req)
  File "/usr/local/lib/python3.6/urllib/request.py", line 504, in _call_chain
    result = func(*args)
  File "/usr/local/lib/python3.6/urllib/request.py", line 1346, in http_open
    return self.do_open(http.client.HTTPConnection, req)
  File "/usr/local/lib/python3.6/urllib/request.py", line 1318, in do_open
    encode_chunked=req.has_header('Transfer-encoding'))
  File "/usr/local/lib/python3.6/http/client.py", line 1239, in request
    self._send_request(method, url, body, headers, encode_chunked)
  File "/usr/local/lib/python3.6/http/client.py", line 1250, in _send_request
    self.putrequest(method, url, **skips)
  File "/usr/local/lib/python3.6/http/client.py", line 1117, in putrequest
    self._output(request.encode('ascii'))
UnicodeEncodeError: 'ascii' codec can't encode characters in position 27-30: ordinal not in range(128)
ERROR:root:http://zeenews.india.com/marathi/news/category/ब्लॉगर्स-पार्क
Traceback (most recent call last):
  File "web_search3.py", line 33, in searchUrl
    urlContent = urllib.request.urlopen(req).read()
  File "/usr/local/lib/python3.6/urllib/request.py", line 223, in urlopen
    return opener.open(url, data, timeout)
  File "/usr/local/lib/python3.6/urllib/request.py", line 526, in open
    response = self._open(req, data)
  File "/usr/local/lib/python3.6/urllib/request.py", line 544, in _open
    '_open', req)
  File "/usr/local/lib/python3.6/urllib/request.py", line 504, in _call_chain
    result = func(*args)
  File "/usr/local/lib/python3.6/urllib/request.py", line 1346, in http_open
    return self.do_open(http.client.HTTPConnection, req)
  File "/usr/local/lib/python3.6/urllib/request.py", line 1318, in do_open
    encode_chunked=req.has_header('Transfer-encoding'))
  File "/usr/local/lib/python3.6/http/client.py", line 1239, in request
    self._send_request(method, url, body, headers, encode_chunked)
  File "/usr/local/lib/python3.6/http/client.py", line 1250, in _send_request
    self.putrequest(method, url, **skips)
  File "/usr/local/lib/python3.6/http/client.py", line 1117, in putrequest
    self._output(request.encode('ascii'))
UnicodeEncodeError: 'ascii' codec can't encode characters in position 27-34: ordinal not in range(128)
ERROR:root:http://zeenews.india.com/marathi/news/category/युथ-क्लब
Traceback (most recent call last):
  File "web_search3.py", line 33, in searchUrl
    urlContent = urllib.request.urlopen(req).read()
  File "/usr/local/lib/python3.6/urllib/request.py", line 223, in urlopen
    return opener.open(url, data, timeout)
  File "/usr/local/lib/python3.6/urllib/request.py", line 526, in open
    response = self._open(req, data)
  File "/usr/local/lib/python3.6/urllib/request.py", line 544, in _open
    '_open', req)
  File "/usr/local/lib/python3.6/urllib/request.py", line 504, in _call_chain
    result = func(*args)
  File "/usr/local/lib/python3.6/urllib/request.py", line 1346, in http_open
    return self.do_open(http.client.HTTPConnection, req)
  File "/usr/local/lib/python3.6/urllib/request.py", line 1318, in do_open
    encode_chunked=req.has_header('Transfer-encoding'))
  File "/usr/local/lib/python3.6/http/client.py", line 1239, in request
    self._send_request(method, url, body, headers, encode_chunked)
  File "/usr/local/lib/python3.6/http/client.py", line 1250, in _send_request
    self.putrequest(method, url, **skips)
  File "/usr/local/lib/python3.6/http/client.py", line 1117, in putrequest
    self._output(request.encode('ascii'))
UnicodeEncodeError: 'ascii' codec can't encode characters in position 27-29: ordinal not in range(128)
ERROR:root:http://zeenews.india.com/marathi/news/category/भविष्य
Traceback (most recent call last):
  File "web_search3.py", line 33, in searchUrl
    urlContent = urllib.request.urlopen(req).read()
  File "/usr/local/lib/python3.6/urllib/request.py", line 223, in urlopen
    return opener.open(url, data, timeout)
  File "/usr/local/lib/python3.6/urllib/request.py", line 526, in open
    response = self._open(req, data)
  File "/usr/local/lib/python3.6/urllib/request.py", line 544, in _open
    '_open', req)
  File "/usr/local/lib/python3.6/urllib/request.py", line 504, in _call_chain
    result = func(*args)
  File "/usr/local/lib/python3.6/urllib/request.py", line 1346, in http_open
    return self.do_open(http.client.HTTPConnection, req)
  File "/usr/local/lib/python3.6/urllib/request.py", line 1318, in do_open
    encode_chunked=req.has_header('Transfer-encoding'))
  File "/usr/local/lib/python3.6/http/client.py", line 1239, in request
    self._send_request(method, url, body, headers, encode_chunked)
  File "/usr/local/lib/python3.6/http/client.py", line 1250, in _send_request
    self.putrequest(method, url, **skips)
  File "/usr/local/lib/python3.6/http/client.py", line 1117, in putrequest
    self._output(request.encode('ascii'))
UnicodeEncodeError: 'ascii' codec can't encode characters in position 27-32: ordinal not in range(128)
ERROR:root:http://indianexpress.com/javascript:void(0)
Traceback (most recent call last):
  File "web_search3.py", line 33, in searchUrl
    urlContent = urllib.request.urlopen(req).read()
  File "/usr/local/lib/python3.6/urllib/request.py", line 223, in urlopen
    return opener.open(url, data, timeout)
  File "/usr/local/lib/python3.6/urllib/request.py", line 532, in open
    response = meth(req, response)
  File "/usr/local/lib/python3.6/urllib/request.py", line 642, in http_response
    'http', request, response, code, msg, hdrs)
  File "/usr/local/lib/python3.6/urllib/request.py", line 570, in error
    return self._call_chain(*args)
  File "/usr/local/lib/python3.6/urllib/request.py", line 504, in _call_chain
    result = func(*args)
  File "/usr/local/lib/python3.6/urllib/request.py", line 650, in http_error_default
    raise HTTPError(req.full_url, code, msg, hdrs, fp)
urllib.error.HTTPError: HTTP Error 404: Not Found
ERROR:root:http://indianexpress.com/../technology/
Traceback (most recent call last):
  File "web_search3.py", line 33, in searchUrl
    urlContent = urllib.request.urlopen(req).read()
  File "/usr/local/lib/python3.6/urllib/request.py", line 223, in urlopen
    return opener.open(url, data, timeout)
  File "/usr/local/lib/python3.6/urllib/request.py", line 532, in open
    response = meth(req, response)
  File "/usr/local/lib/python3.6/urllib/request.py", line 642, in http_response
    'http', request, response, code, msg, hdrs)
  File "/usr/local/lib/python3.6/urllib/request.py", line 570, in error
    return self._call_chain(*args)
  File "/usr/local/lib/python3.6/urllib/request.py", line 504, in _call_chain
    result = func(*args)
  File "/usr/local/lib/python3.6/urllib/request.py", line 650, in http_error_default
    raise HTTPError(req.full_url, code, msg, hdrs, fp)
urllib.error.HTTPError: HTTP Error 400: Bad Request
ERROR:root:http://indianexpress.com/../business/
Traceback (most recent call last):
  File "web_search3.py", line 33, in searchUrl
    urlContent = urllib.request.urlopen(req).read()
  File "/usr/local/lib/python3.6/urllib/request.py", line 223, in urlopen
    return opener.open(url, data, timeout)
  File "/usr/local/lib/python3.6/urllib/request.py", line 532, in open
    response = meth(req, response)
  File "/usr/local/lib/python3.6/urllib/request.py", line 642, in http_response
    'http', request, response, code, msg, hdrs)
  File "/usr/local/lib/python3.6/urllib/request.py", line 570, in error
    return self._call_chain(*args)
  File "/usr/local/lib/python3.6/urllib/request.py", line 504, in _call_chain
    result = func(*args)
  File "/usr/local/lib/python3.6/urllib/request.py", line 650, in http_error_default
    raise HTTPError(req.full_url, code, msg, hdrs, fp)
urllib.error.HTTPError: HTTP Error 400: Bad Request
ERROR:root:http://indianexpress.com/../lifestyle/
Traceback (most recent call last):
  File "web_search3.py", line 33, in searchUrl
    urlContent = urllib.request.urlopen(req).read()
  File "/usr/local/lib/python3.6/urllib/request.py", line 223, in urlopen
    return opener.open(url, data, timeout)
  File "/usr/local/lib/python3.6/urllib/request.py", line 532, in open
    response = meth(req, response)
  File "/usr/local/lib/python3.6/urllib/request.py", line 642, in http_response
    'http', request, response, code, msg, hdrs)
  File "/usr/local/lib/python3.6/urllib/request.py", line 570, in error
    return self._call_chain(*args)
  File "/usr/local/lib/python3.6/urllib/request.py", line 504, in _call_chain
    result = func(*args)
  File "/usr/local/lib/python3.6/urllib/request.py", line 650, in http_error_default
    raise HTTPError(req.full_url, code, msg, hdrs, fp)
urllib.error.HTTPError: HTTP Error 400: Bad Request
ERROR:root:http://www.sundayguardianlive.com/the-b-list
Traceback (most recent call last):
  File "web_search3.py", line 33, in searchUrl
    urlContent = urllib.request.urlopen(req).read()
  File "/usr/local/lib/python3.6/urllib/request.py", line 223, in urlopen
    return opener.open(url, data, timeout)
  File "/usr/local/lib/python3.6/urllib/request.py", line 532, in open
    response = meth(req, response)
  File "/usr/local/lib/python3.6/urllib/request.py", line 642, in http_response
    'http', request, response, code, msg, hdrs)
  File "/usr/local/lib/python3.6/urllib/request.py", line 570, in error
    return self._call_chain(*args)
  File "/usr/local/lib/python3.6/urllib/request.py", line 504, in _call_chain
    result = func(*args)
  File "/usr/local/lib/python3.6/urllib/request.py", line 650, in http_error_default
    raise HTTPError(req.full_url, code, msg, hdrs, fp)
urllib.error.HTTPError: HTTP Error 404: Not Found
ERROR:root:http://www.sundayguardianlive.com/mailto:letters@sunday-guardian.com
Traceback (most recent call last):
  File "web_search3.py", line 33, in searchUrl
    urlContent = urllib.request.urlopen(req).read()
  File "/usr/local/lib/python3.6/urllib/request.py", line 223, in urlopen
    return opener.open(url, data, timeout)
  File "/usr/local/lib/python3.6/urllib/request.py", line 532, in open
    response = meth(req, response)
  File "/usr/local/lib/python3.6/urllib/request.py", line 642, in http_response
    'http', request, response, code, msg, hdrs)
  File "/usr/local/lib/python3.6/urllib/request.py", line 570, in error
    return self._call_chain(*args)
  File "/usr/local/lib/python3.6/urllib/request.py", line 504, in _call_chain
    result = func(*args)
  File "/usr/local/lib/python3.6/urllib/request.py", line 650, in http_error_default
    raise HTTPError(req.full_url, code, msg, hdrs, fp)
urllib.error.HTTPError: HTTP Error 404: Not Found
ERROR:root:http://www.hindustantimes.com/javascript:void(0)
Traceback (most recent call last):
  File "web_search3.py", line 33, in searchUrl
    urlContent = urllib.request.urlopen(req).read()
  File "/usr/local/lib/python3.6/urllib/request.py", line 223, in urlopen
    return opener.open(url, data, timeout)
  File "/usr/local/lib/python3.6/urllib/request.py", line 532, in open
    response = meth(req, response)
  File "/usr/local/lib/python3.6/urllib/request.py", line 642, in http_response
    'http', request, response, code, msg, hdrs)
  File "/usr/local/lib/python3.6/urllib/request.py", line 570, in error
    return self._call_chain(*args)
  File "/usr/local/lib/python3.6/urllib/request.py", line 504, in _call_chain
    result = func(*args)
  File "/usr/local/lib/python3.6/urllib/request.py", line 650, in http_error_default
    raise HTTPError(req.full_url, code, msg, hdrs, fp)
urllib.error.HTTPError: HTTP Error 404: Not Found
ERROR:root:http://www.hindustantimes.com/ /india-news/
Traceback (most recent call last):
  File "web_search3.py", line 33, in searchUrl
    urlContent = urllib.request.urlopen(req).read()
  File "/usr/local/lib/python3.6/urllib/request.py", line 223, in urlopen
    return opener.open(url, data, timeout)
  File "/usr/local/lib/python3.6/urllib/request.py", line 532, in open
    response = meth(req, response)
  File "/usr/local/lib/python3.6/urllib/request.py", line 642, in http_response
    'http', request, response, code, msg, hdrs)
  File "/usr/local/lib/python3.6/urllib/request.py", line 570, in error
    return self._call_chain(*args)
  File "/usr/local/lib/python3.6/urllib/request.py", line 504, in _call_chain
    result = func(*args)
  File "/usr/local/lib/python3.6/urllib/request.py", line 650, in http_error_default
    raise HTTPError(req.full_url, code, msg, hdrs, fp)
urllib.error.HTTPError: HTTP Error 400: Bad Request
ERROR:root:http://www.hindustantimes.com/ /world-news/
Traceback (most recent call last):
  File "web_search3.py", line 33, in searchUrl
    urlContent = urllib.request.urlopen(req).read()
  File "/usr/local/lib/python3.6/urllib/request.py", line 223, in urlopen
    return opener.open(url, data, timeout)
  File "/usr/local/lib/python3.6/urllib/request.py", line 532, in open
    response = meth(req, response)
  File "/usr/local/lib/python3.6/urllib/request.py", line 642, in http_response
    'http', request, response, code, msg, hdrs)
  File "/usr/local/lib/python3.6/urllib/request.py", line 570, in error
    return self._call_chain(*args)
  File "/usr/local/lib/python3.6/urllib/request.py", line 504, in _call_chain
    result = func(*args)
  File "/usr/local/lib/python3.6/urllib/request.py", line 650, in http_error_default
    raise HTTPError(req.full_url, code, msg, hdrs, fp)
urllib.error.HTTPError: HTTP Error 400: Bad Request
ERROR:root:http://www.hindustantimes.com/ /opinion/
Traceback (most recent call last):
  File "web_search3.py", line 33, in searchUrl
    urlContent = urllib.request.urlopen(req).read()
  File "/usr/local/lib/python3.6/urllib/request.py", line 223, in urlopen
    return opener.open(url, data, timeout)
  File "/usr/local/lib/python3.6/urllib/request.py", line 532, in open
    response = meth(req, response)
  File "/usr/local/lib/python3.6/urllib/request.py", line 642, in http_response
    'http', request, response, code, msg, hdrs)
  File "/usr/local/lib/python3.6/urllib/request.py", line 570, in error
    return self._call_chain(*args)
  File "/usr/local/lib/python3.6/urllib/request.py", line 504, in _call_chain
    result = func(*args)
  File "/usr/local/lib/python3.6/urllib/request.py", line 650, in http_error_default
    raise HTTPError(req.full_url, code, msg, hdrs, fp)
urllib.error.HTTPError: HTTP Error 400: Bad Request
ERROR:root:http://www.hindustantimes.com/ /india-vs-west-indies-2017/
Traceback (most recent call last):
  File "web_search3.py", line 33, in searchUrl
    urlContent = urllib.request.urlopen(req).read()
  File "/usr/local/lib/python3.6/urllib/request.py", line 223, in urlopen
    return opener.open(url, data, timeout)
  File "/usr/local/lib/python3.6/urllib/request.py", line 532, in open
    response = meth(req, response)
  File "/usr/local/lib/python3.6/urllib/request.py", line 642, in http_response
    'http', request, response, code, msg, hdrs)
  File "/usr/local/lib/python3.6/urllib/request.py", line 570, in error
    return self._call_chain(*args)
  File "/usr/local/lib/python3.6/urllib/request.py", line 504, in _call_chain
    result = func(*args)
  File "/usr/local/lib/python3.6/urllib/request.py", line 650, in http_error_default
    raise HTTPError(req.full_url, code, msg, hdrs, fp)
urllib.error.HTTPError: HTTP Error 400: Bad Request
ERROR:root:http://www.hindustantimes.com/ /sports-news/
Traceback (most recent call last):
  File "web_search3.py", line 33, in searchUrl
    urlContent = urllib.request.urlopen(req).read()
  File "/usr/local/lib/python3.6/urllib/request.py", line 223, in urlopen
    return opener.open(url, data, timeout)
  File "/usr/local/lib/python3.6/urllib/request.py", line 532, in open
    response = meth(req, response)
  File "/usr/local/lib/python3.6/urllib/request.py", line 642, in http_response
    'http', request, response, code, msg, hdrs)
  File "/usr/local/lib/python3.6/urllib/request.py", line 570, in error
    return self._call_chain(*args)
  File "/usr/local/lib/python3.6/urllib/request.py", line 504, in _call_chain
    result = func(*args)
  File "/usr/local/lib/python3.6/urllib/request.py", line 650, in http_error_default
    raise HTTPError(req.full_url, code, msg, hdrs, fp)
urllib.error.HTTPError: HTTP Error 400: Bad Request
ERROR:root:http://www.hindustantimes.com/ /entertainment/
Traceback (most recent call last):
  File "web_search3.py", line 33, in searchUrl
    urlContent = urllib.request.urlopen(req).read()
  File "/usr/local/lib/python3.6/urllib/request.py", line 223, in urlopen
    return opener.open(url, data, timeout)
  File "/usr/local/lib/python3.6/urllib/request.py", line 532, in open
    response = meth(req, response)
  File "/usr/local/lib/python3.6/urllib/request.py", line 642, in http_response
    'http', request, response, code, msg, hdrs)
  File "/usr/local/lib/python3.6/urllib/request.py", line 570, in error
    return self._call_chain(*args)
  File "/usr/local/lib/python3.6/urllib/request.py", line 504, in _call_chain
    result = func(*args)
  File "/usr/local/lib/python3.6/urllib/request.py", line 650, in http_error_default
    raise HTTPError(req.full_url, code, msg, hdrs, fp)
urllib.error.HTTPError: HTTP Error 400: Bad Request
ERROR:root:http://www.hindustantimes.com/ /lifestyle/
Traceback (most recent call last):
  File "web_search3.py", line 33, in searchUrl
    urlContent = urllib.request.urlopen(req).read()
  File "/usr/local/lib/python3.6/urllib/request.py", line 223, in urlopen
    return opener.open(url, data, timeout)
  File "/usr/local/lib/python3.6/urllib/request.py", line 532, in open
    response = meth(req, response)
  File "/usr/local/lib/python3.6/urllib/request.py", line 642, in http_response
    'http', request, response, code, msg, hdrs)
  File "/usr/local/lib/python3.6/urllib/request.py", line 570, in error
    return self._call_chain(*args)
  File "/usr/local/lib/python3.6/urllib/request.py", line 504, in _call_chain
    result = func(*args)
  File "/usr/local/lib/python3.6/urllib/request.py", line 650, in http_error_default
    raise HTTPError(req.full_url, code, msg, hdrs, fp)
urllib.error.HTTPError: HTTP Error 400: Bad Request
ERROR:root:http://www.hindustantimes.com/ /business-news/
Traceback (most recent call last):
  File "web_search3.py", line 33, in searchUrl
    urlContent = urllib.request.urlopen(req).read()
  File "/usr/local/lib/python3.6/urllib/request.py", line 223, in urlopen
    return opener.open(url, data, timeout)
  File "/usr/local/lib/python3.6/urllib/request.py", line 532, in open
    response = meth(req, response)
  File "/usr/local/lib/python3.6/urllib/request.py", line 642, in http_response
    'http', request, response, code, msg, hdrs)
  File "/usr/local/lib/python3.6/urllib/request.py", line 570, in error
    return self._call_chain(*args)
  File "/usr/local/lib/python3.6/urllib/request.py", line 504, in _call_chain
    result = func(*args)
  File "/usr/local/lib/python3.6/urllib/request.py", line 650, in http_error_default
    raise HTTPError(req.full_url, code, msg, hdrs, fp)
urllib.error.HTTPError: HTTP Error 400: Bad Request
ERROR:root:http://www.hindustantimes.com/ /tech/
Traceback (most recent call last):
  File "web_search3.py", line 33, in searchUrl
    urlContent = urllib.request.urlopen(req).read()
  File "/usr/local/lib/python3.6/urllib/request.py", line 223, in urlopen
    return opener.open(url, data, timeout)
  File "/usr/local/lib/python3.6/urllib/request.py", line 532, in open
    response = meth(req, response)
  File "/usr/local/lib/python3.6/urllib/request.py", line 642, in http_response
    'http', request, response, code, msg, hdrs)
  File "/usr/local/lib/python3.6/urllib/request.py", line 570, in error
    return self._call_chain(*args)
  File "/usr/local/lib/python3.6/urllib/request.py", line 504, in _call_chain
    result = func(*args)
  File "/usr/local/lib/python3.6/urllib/request.py", line 650, in http_error_default
    raise HTTPError(req.full_url, code, msg, hdrs, fp)
urllib.error.HTTPError: HTTP Error 400: Bad Request
ERROR:root:http://www.hindustantimes.com/ /education/
Traceback (most recent call last):
  File "web_search3.py", line 33, in searchUrl
    urlContent = urllib.request.urlopen(req).read()
  File "/usr/local/lib/python3.6/urllib/request.py", line 223, in urlopen
    return opener.open(url, data, timeout)
  File "/usr/local/lib/python3.6/urllib/request.py", line 532, in open
    response = meth(req, response)
  File "/usr/local/lib/python3.6/urllib/request.py", line 642, in http_response
    'http', request, response, code, msg, hdrs)
  File "/usr/local/lib/python3.6/urllib/request.py", line 570, in error
    return self._call_chain(*args)
  File "/usr/local/lib/python3.6/urllib/request.py", line 504, in _call_chain
    result = func(*args)
  File "/usr/local/lib/python3.6/urllib/request.py", line 650, in http_error_default
    raise HTTPError(req.full_url, code, msg, hdrs, fp)
urllib.error.HTTPError: HTTP Error 400: Bad Request
ERROR:root:http://www.hindustantimes.com/ /what-now/
Traceback (most recent call last):
  File "web_search3.py", line 33, in searchUrl
    urlContent = urllib.request.urlopen(req).read()
  File "/usr/local/lib/python3.6/urllib/request.py", line 223, in urlopen
    return opener.open(url, data, timeout)
  File "/usr/local/lib/python3.6/urllib/request.py", line 532, in open
    response = meth(req, response)
  File "/usr/local/lib/python3.6/urllib/request.py", line 642, in http_response
    'http', request, response, code, msg, hdrs)
  File "/usr/local/lib/python3.6/urllib/request.py", line 570, in error
    return self._call_chain(*args)
  File "/usr/local/lib/python3.6/urllib/request.py", line 504, in _call_chain
    result = func(*args)
  File "/usr/local/lib/python3.6/urllib/request.py", line 650, in http_error_default
    raise HTTPError(req.full_url, code, msg, hdrs, fp)
urllib.error.HTTPError: HTTP Error 400: Bad Request
ERROR:root:http://www.hindustantimes.com/ /photos/
Traceback (most recent call last):
  File "web_search3.py", line 33, in searchUrl
    urlContent = urllib.request.urlopen(req).read()
  File "/usr/local/lib/python3.6/urllib/request.py", line 223, in urlopen
    return opener.open(url, data, timeout)
  File "/usr/local/lib/python3.6/urllib/request.py", line 532, in open
    response = meth(req, response)
  File "/usr/local/lib/python3.6/urllib/request.py", line 642, in http_response
    'http', request, response, code, msg, hdrs)
  File "/usr/local/lib/python3.6/urllib/request.py", line 570, in error
    return self._call_chain(*args)
  File "/usr/local/lib/python3.6/urllib/request.py", line 504, in _call_chain
    result = func(*args)
  File "/usr/local/lib/python3.6/urllib/request.py", line 650, in http_error_default
    raise HTTPError(req.full_url, code, msg, hdrs, fp)
urllib.error.HTTPError: HTTP Error 400: Bad Request
ERROR:root:http://www.hindustantimes.com/ /videos/
Traceback (most recent call last):
  File "web_search3.py", line 33, in searchUrl
    urlContent = urllib.request.urlopen(req).read()
  File "/usr/local/lib/python3.6/urllib/request.py", line 223, in urlopen
    return opener.open(url, data, timeout)
  File "/usr/local/lib/python3.6/urllib/request.py", line 532, in open
    response = meth(req, response)
  File "/usr/local/lib/python3.6/urllib/request.py", line 642, in http_response
    'http', request, response, code, msg, hdrs)
  File "/usr/local/lib/python3.6/urllib/request.py", line 570, in error
    return self._call_chain(*args)
  File "/usr/local/lib/python3.6/urllib/request.py", line 504, in _call_chain
    result = func(*args)
  File "/usr/local/lib/python3.6/urllib/request.py", line 650, in http_error_default
    raise HTTPError(req.full_url, code, msg, hdrs, fp)
urllib.error.HTTPError: HTTP Error 400: Bad Request
ERROR:root:http://www.hindustantimes.com/photos/cricket/
Traceback (most recent call last):
  File "web_search3.py", line 33, in searchUrl
    urlContent = urllib.request.urlopen(req).read()
  File "/usr/local/lib/python3.6/urllib/request.py", line 223, in urlopen
    return opener.open(url, data, timeout)
  File "/usr/local/lib/python3.6/urllib/request.py", line 532, in open
    response = meth(req, response)
  File "/usr/local/lib/python3.6/urllib/request.py", line 642, in http_response
    'http', request, response, code, msg, hdrs)
  File "/usr/local/lib/python3.6/urllib/request.py", line 570, in error
    return self._call_chain(*args)
  File "/usr/local/lib/python3.6/urllib/request.py", line 504, in _call_chain
    result = func(*args)
  File "/usr/local/lib/python3.6/urllib/request.py", line 650, in http_error_default
    raise HTTPError(req.full_url, code, msg, hdrs, fp)
urllib.error.HTTPError: HTTP Error 404: Not Found
ERROR:root:http://www.theguardian.com/
    
        https://contribute.theguardian.com/us?INTCMP=gdnwb_copts_co_dotcom_header
    
Traceback (most recent call last):
  File "web_search3.py", line 33, in searchUrl
    urlContent = urllib.request.urlopen(req).read()
  File "/usr/local/lib/python3.6/urllib/request.py", line 223, in urlopen
    return opener.open(url, data, timeout)
  File "/usr/local/lib/python3.6/urllib/request.py", line 532, in open
    response = meth(req, response)
  File "/usr/local/lib/python3.6/urllib/request.py", line 642, in http_response
    'http', request, response, code, msg, hdrs)
  File "/usr/local/lib/python3.6/urllib/request.py", line 570, in error
    return self._call_chain(*args)
  File "/usr/local/lib/python3.6/urllib/request.py", line 504, in _call_chain
    result = func(*args)
  File "/usr/local/lib/python3.6/urllib/request.py", line 650, in http_error_default
    raise HTTPError(req.full_url, code, msg, hdrs, fp)
urllib.error.HTTPError: HTTP Error 400: Bad Request
ERROR:root:http://www.theguardian.com/
    
        https://jobs.theguardian.com?INTCMP=jobs_us_web_newheader
    
Traceback (most recent call last):
  File "web_search3.py", line 33, in searchUrl
    urlContent = urllib.request.urlopen(req).read()
  File "/usr/local/lib/python3.6/urllib/request.py", line 223, in urlopen
    return opener.open(url, data, timeout)
  File "/usr/local/lib/python3.6/urllib/request.py", line 532, in open
    response = meth(req, response)
  File "/usr/local/lib/python3.6/urllib/request.py", line 642, in http_response
    'http', request, response, code, msg, hdrs)
  File "/usr/local/lib/python3.6/urllib/request.py", line 570, in error
    return self._call_chain(*args)
  File "/usr/local/lib/python3.6/urllib/request.py", line 504, in _call_chain
    result = func(*args)
  File "/usr/local/lib/python3.6/urllib/request.py", line 650, in http_error_default
    raise HTTPError(req.full_url, code, msg, hdrs, fp)
urllib.error.HTTPError: HTTP Error 400: Bad Request
ERROR:root:http://www.ndtv.com/javascript:void(0)
Traceback (most recent call last):
  File "web_search3.py", line 33, in searchUrl
    urlContent = urllib.request.urlopen(req).read()
  File "/usr/local/lib/python3.6/urllib/request.py", line 223, in urlopen
    return opener.open(url, data, timeout)
  File "/usr/local/lib/python3.6/urllib/request.py", line 532, in open
    response = meth(req, response)
  File "/usr/local/lib/python3.6/urllib/request.py", line 642, in http_response
    'http', request, response, code, msg, hdrs)
  File "/usr/local/lib/python3.6/urllib/request.py", line 570, in error
    return self._call_chain(*args)
  File "/usr/local/lib/python3.6/urllib/request.py", line 504, in _call_chain
    result = func(*args)
  File "/usr/local/lib/python3.6/urllib/request.py", line 650, in http_error_default
    raise HTTPError(req.full_url, code, msg, hdrs, fp)
urllib.error.HTTPError: HTTP Error 404: Not Found
ERROR:root:http://www.ndtv.com/ https://sports.ndtv.com?pfrom=home-sports
Traceback (most recent call last):
  File "web_search3.py", line 33, in searchUrl
    urlContent = urllib.request.urlopen(req).read()
  File "/usr/local/lib/python3.6/urllib/request.py", line 223, in urlopen
    return opener.open(url, data, timeout)
  File "/usr/local/lib/python3.6/urllib/request.py", line 532, in open
    response = meth(req, response)
  File "/usr/local/lib/python3.6/urllib/request.py", line 642, in http_response
    'http', request, response, code, msg, hdrs)
  File "/usr/local/lib/python3.6/urllib/request.py", line 570, in error
    return self._call_chain(*args)
  File "/usr/local/lib/python3.6/urllib/request.py", line 504, in _call_chain
    result = func(*args)
  File "/usr/local/lib/python3.6/urllib/request.py", line 650, in http_error_default
    raise HTTPError(req.full_url, code, msg, hdrs, fp)
urllib.error.HTTPError: HTTP Error 400: Bad Request
ERROR:root:http://www.ndtv.com/javascript:void()
Traceback (most recent call last):
  File "web_search3.py", line 33, in searchUrl
    urlContent = urllib.request.urlopen(req).read()
  File "/usr/local/lib/python3.6/urllib/request.py", line 223, in urlopen
    return opener.open(url, data, timeout)
  File "/usr/local/lib/python3.6/urllib/request.py", line 532, in open
    response = meth(req, response)
  File "/usr/local/lib/python3.6/urllib/request.py", line 642, in http_response
    'http', request, response, code, msg, hdrs)
  File "/usr/local/lib/python3.6/urllib/request.py", line 570, in error
    return self._call_chain(*args)
  File "/usr/local/lib/python3.6/urllib/request.py", line 504, in _call_chain
    result = func(*args)
  File "/usr/local/lib/python3.6/urllib/request.py", line 650, in http_error_default
    raise HTTPError(req.full_url, code, msg, hdrs, fp)
urllib.error.HTTPError: HTTP Error 404: Not Found
ERROR:root:http://www.news18.com/javascript:void(0)
Traceback (most recent call last):
  File "web_search3.py", line 33, in searchUrl
    urlContent = urllib.request.urlopen(req).read()
  File "/usr/local/lib/python3.6/urllib/request.py", line 223, in urlopen
    return opener.open(url, data, timeout)
  File "/usr/local/lib/python3.6/urllib/request.py", line 532, in open
    response = meth(req, response)
  File "/usr/local/lib/python3.6/urllib/request.py", line 642, in http_response
    'http', request, response, code, msg, hdrs)
  File "/usr/local/lib/python3.6/urllib/request.py", line 564, in error
    result = self._call_chain(*args)
  File "/usr/local/lib/python3.6/urllib/request.py", line 504, in _call_chain
    result = func(*args)
  File "/usr/local/lib/python3.6/urllib/request.py", line 756, in http_error_302
    return self.parent.open(new, timeout=req.timeout)
  File "/usr/local/lib/python3.6/urllib/request.py", line 532, in open
    response = meth(req, response)
  File "/usr/local/lib/python3.6/urllib/request.py", line 642, in http_response
    'http', request, response, code, msg, hdrs)
  File "/usr/local/lib/python3.6/urllib/request.py", line 570, in error
    return self._call_chain(*args)
  File "/usr/local/lib/python3.6/urllib/request.py", line 504, in _call_chain
    result = func(*args)
  File "/usr/local/lib/python3.6/urllib/request.py", line 650, in http_error_default
    raise HTTPError(req.full_url, code, msg, hdrs, fp)
urllib.error.HTTPError: HTTP Error 404: Not Found
ERROR:root:http://www.news18.com/news/india/%e2%80%8eup-police-cracks-down-on-dalits-trying-to-gift-150kg-soap-to-yogi-adityanath-1450649.html
Traceback (most recent call last):
  File "web_search3.py", line 33, in searchUrl
    urlContent = urllib.request.urlopen(req).read()
  File "/usr/local/lib/python3.6/urllib/request.py", line 223, in urlopen
    return opener.open(url, data, timeout)
  File "/usr/local/lib/python3.6/urllib/request.py", line 532, in open
    response = meth(req, response)
  File "/usr/local/lib/python3.6/urllib/request.py", line 642, in http_response
    'http', request, response, code, msg, hdrs)
  File "/usr/local/lib/python3.6/urllib/request.py", line 564, in error
    result = self._call_chain(*args)
  File "/usr/local/lib/python3.6/urllib/request.py", line 504, in _call_chain
    result = func(*args)
  File "/usr/local/lib/python3.6/urllib/request.py", line 756, in http_error_302
    return self.parent.open(new, timeout=req.timeout)
  File "/usr/local/lib/python3.6/urllib/request.py", line 532, in open
    response = meth(req, response)
  File "/usr/local/lib/python3.6/urllib/request.py", line 642, in http_response
    'http', request, response, code, msg, hdrs)
  File "/usr/local/lib/python3.6/urllib/request.py", line 564, in error
    result = self._call_chain(*args)
  File "/usr/local/lib/python3.6/urllib/request.py", line 504, in _call_chain
    result = func(*args)
  File "/usr/local/lib/python3.6/urllib/request.py", line 756, in http_error_302
    return self.parent.open(new, timeout=req.timeout)
  File "/usr/local/lib/python3.6/urllib/request.py", line 532, in open
    response = meth(req, response)
  File "/usr/local/lib/python3.6/urllib/request.py", line 642, in http_response
    'http', request, response, code, msg, hdrs)
  File "/usr/local/lib/python3.6/urllib/request.py", line 564, in error
    result = self._call_chain(*args)
  File "/usr/local/lib/python3.6/urllib/request.py", line 504, in _call_chain
    result = func(*args)
  File "/usr/local/lib/python3.6/urllib/request.py", line 756, in http_error_302
    return self.parent.open(new, timeout=req.timeout)
  File "/usr/local/lib/python3.6/urllib/request.py", line 532, in open
    response = meth(req, response)
  File "/usr/local/lib/python3.6/urllib/request.py", line 642, in http_response
    'http', request, response, code, msg, hdrs)
  File "/usr/local/lib/python3.6/urllib/request.py", line 564, in error
    result = self._call_chain(*args)
  File "/usr/local/lib/python3.6/urllib/request.py", line 504, in _call_chain
    result = func(*args)
  File "/usr/local/lib/python3.6/urllib/request.py", line 756, in http_error_302
    return self.parent.open(new, timeout=req.timeout)
  File "/usr/local/lib/python3.6/urllib/request.py", line 532, in open
    response = meth(req, response)
  File "/usr/local/lib/python3.6/urllib/request.py", line 642, in http_response
    'http', request, response, code, msg, hdrs)
  File "/usr/local/lib/python3.6/urllib/request.py", line 564, in error
    result = self._call_chain(*args)
  File "/usr/local/lib/python3.6/urllib/request.py", line 504, in _call_chain
    result = func(*args)
  File "/usr/local/lib/python3.6/urllib/request.py", line 746, in http_error_302
    self.inf_msg + msg, headers, fp)
urllib.error.HTTPError: HTTP Error 301: The HTTP server returned a redirect error that would lead to an infinite loop.
The last 30x error message was:
Moved Permanently
ERROR:root:http://www.news18.com/javascript:void(0)
Traceback (most recent call last):
  File "web_search3.py", line 33, in searchUrl
    urlContent = urllib.request.urlopen(req).read()
  File "/usr/local/lib/python3.6/urllib/request.py", line 223, in urlopen
    return opener.open(url, data, timeout)
  File "/usr/local/lib/python3.6/urllib/request.py", line 532, in open
    response = meth(req, response)
  File "/usr/local/lib/python3.6/urllib/request.py", line 642, in http_response
    'http', request, response, code, msg, hdrs)
  File "/usr/local/lib/python3.6/urllib/request.py", line 564, in error
    result = self._call_chain(*args)
  File "/usr/local/lib/python3.6/urllib/request.py", line 504, in _call_chain
    result = func(*args)
  File "/usr/local/lib/python3.6/urllib/request.py", line 756, in http_error_302
    return self.parent.open(new, timeout=req.timeout)
  File "/usr/local/lib/python3.6/urllib/request.py", line 532, in open
    response = meth(req, response)
  File "/usr/local/lib/python3.6/urllib/request.py", line 642, in http_response
    'http', request, response, code, msg, hdrs)
  File "/usr/local/lib/python3.6/urllib/request.py", line 570, in error
    return self._call_chain(*args)
  File "/usr/local/lib/python3.6/urllib/request.py", line 504, in _call_chain
    result = func(*args)
  File "/usr/local/lib/python3.6/urllib/request.py", line 650, in http_error_default
    raise HTTPError(req.full_url, code, msg, hdrs, fp)
urllib.error.HTTPError: HTTP Error 404: Not Found
ERROR:root:http://www.livemint.com/javascript:void(0)
Traceback (most recent call last):
  File "web_search3.py", line 33, in searchUrl
    urlContent = urllib.request.urlopen(req).read()
  File "/usr/local/lib/python3.6/urllib/request.py", line 223, in urlopen
    return opener.open(url, data, timeout)
  File "/usr/local/lib/python3.6/urllib/request.py", line 532, in open
    response = meth(req, response)
  File "/usr/local/lib/python3.6/urllib/request.py", line 642, in http_response
    'http', request, response, code, msg, hdrs)
  File "/usr/local/lib/python3.6/urllib/request.py", line 570, in error
    return self._call_chain(*args)
  File "/usr/local/lib/python3.6/urllib/request.py", line 504, in _call_chain
    result = func(*args)
  File "/usr/local/lib/python3.6/urllib/request.py", line 650, in http_error_default
    raise HTTPError(req.full_url, code, msg, hdrs, fp)
urllib.error.HTTPError: HTTP Error 404: Not Found
ERROR:root:http://www.livemint.com/javascript:void(0)
Traceback (most recent call last):
  File "web_search3.py", line 33, in searchUrl
    urlContent = urllib.request.urlopen(req).read()
  File "/usr/local/lib/python3.6/urllib/request.py", line 223, in urlopen
    return opener.open(url, data, timeout)
  File "/usr/local/lib/python3.6/urllib/request.py", line 532, in open
    response = meth(req, response)
  File "/usr/local/lib/python3.6/urllib/request.py", line 642, in http_response
    'http', request, response, code, msg, hdrs)
  File "/usr/local/lib/python3.6/urllib/request.py", line 570, in error
    return self._call_chain(*args)
  File "/usr/local/lib/python3.6/urllib/request.py", line 504, in _call_chain
    result = func(*args)
  File "/usr/local/lib/python3.6/urllib/request.py", line 650, in http_error_default
    raise HTTPError(req.full_url, code, msg, hdrs, fp)
urllib.error.HTTPError: HTTP Error 404: Not Found
ERROR:root:http://www.sirfnews.com/mailto:write@sirfnews.com
Traceback (most recent call last):
  File "web_search3.py", line 33, in searchUrl
    urlContent = urllib.request.urlopen(req).read()
  File "/usr/local/lib/python3.6/urllib/request.py", line 223, in urlopen
    return opener.open(url, data, timeout)
  File "/usr/local/lib/python3.6/urllib/request.py", line 532, in open
    response = meth(req, response)
  File "/usr/local/lib/python3.6/urllib/request.py", line 642, in http_response
    'http', request, response, code, msg, hdrs)
  File "/usr/local/lib/python3.6/urllib/request.py", line 570, in error
    return self._call_chain(*args)
  File "/usr/local/lib/python3.6/urllib/request.py", line 504, in _call_chain
    result = func(*args)
  File "/usr/local/lib/python3.6/urllib/request.py", line 650, in http_error_default
    raise HTTPError(req.full_url, code, msg, hdrs, fp)
urllib.error.HTTPError: HTTP Error 404: Not Found
ERROR:root:http://www.sirfnews.com/category/dharma
Traceback (most recent call last):
  File "web_search3.py", line 33, in searchUrl
    urlContent = urllib.request.urlopen(req).read()
  File "/usr/local/lib/python3.6/urllib/request.py", line 223, in urlopen
    return opener.open(url, data, timeout)
  File "/usr/local/lib/python3.6/urllib/request.py", line 532, in open
    response = meth(req, response)
  File "/usr/local/lib/python3.6/urllib/request.py", line 642, in http_response
    'http', request, response, code, msg, hdrs)
  File "/usr/local/lib/python3.6/urllib/request.py", line 570, in error
    return self._call_chain(*args)
  File "/usr/local/lib/python3.6/urllib/request.py", line 504, in _call_chain
    result = func(*args)
  File "/usr/local/lib/python3.6/urllib/request.py", line 650, in http_error_default
    raise HTTPError(req.full_url, code, msg, hdrs, fp)
urllib.error.HTTPError: HTTP Error 404: Not Found
ERROR:root:http://www.sirfnews.com/mailto:editor@sirfnews.com
Traceback (most recent call last):
  File "web_search3.py", line 33, in searchUrl
    urlContent = urllib.request.urlopen(req).read()
  File "/usr/local/lib/python3.6/urllib/request.py", line 223, in urlopen
    return opener.open(url, data, timeout)
  File "/usr/local/lib/python3.6/urllib/request.py", line 532, in open
    response = meth(req, response)
  File "/usr/local/lib/python3.6/urllib/request.py", line 642, in http_response
    'http', request, response, code, msg, hdrs)
  File "/usr/local/lib/python3.6/urllib/request.py", line 570, in error
    return self._call_chain(*args)
  File "/usr/local/lib/python3.6/urllib/request.py", line 504, in _call_chain
    result = func(*args)
  File "/usr/local/lib/python3.6/urllib/request.py", line 650, in http_error_default
    raise HTTPError(req.full_url, code, msg, hdrs, fp)
urllib.error.HTTPError: HTTP Error 404: Not Found
ERROR:root:http://in.reuters.com//af.reuters.com
Traceback (most recent call last):
  File "web_search3.py", line 33, in searchUrl
    urlContent = urllib.request.urlopen(req).read()
  File "/usr/local/lib/python3.6/urllib/request.py", line 223, in urlopen
    return opener.open(url, data, timeout)
  File "/usr/local/lib/python3.6/urllib/request.py", line 532, in open
    response = meth(req, response)
  File "/usr/local/lib/python3.6/urllib/request.py", line 642, in http_response
    'http', request, response, code, msg, hdrs)
  File "/usr/local/lib/python3.6/urllib/request.py", line 570, in error
    return self._call_chain(*args)
  File "/usr/local/lib/python3.6/urllib/request.py", line 504, in _call_chain
    result = func(*args)
  File "/usr/local/lib/python3.6/urllib/request.py", line 650, in http_error_default
    raise HTTPError(req.full_url, code, msg, hdrs, fp)
urllib.error.HTTPError: HTTP Error 404: Not Found
ERROR:root:http://in.reuters.com//lta.reuters.com
Traceback (most recent call last):
  File "web_search3.py", line 33, in searchUrl
    urlContent = urllib.request.urlopen(req).read()
  File "/usr/local/lib/python3.6/urllib/request.py", line 223, in urlopen
    return opener.open(url, data, timeout)
  File "/usr/local/lib/python3.6/urllib/request.py", line 532, in open
    response = meth(req, response)
  File "/usr/local/lib/python3.6/urllib/request.py", line 642, in http_response
    'http', request, response, code, msg, hdrs)
  File "/usr/local/lib/python3.6/urllib/request.py", line 570, in error
    return self._call_chain(*args)
  File "/usr/local/lib/python3.6/urllib/request.py", line 504, in _call_chain
    result = func(*args)
  File "/usr/local/lib/python3.6/urllib/request.py", line 650, in http_error_default
    raise HTTPError(req.full_url, code, msg, hdrs, fp)
urllib.error.HTTPError: HTTP Error 404: Not Found
ERROR:root:http://in.reuters.com//ara.reuters.com
Traceback (most recent call last):
  File "web_search3.py", line 33, in searchUrl
    urlContent = urllib.request.urlopen(req).read()
  File "/usr/local/lib/python3.6/urllib/request.py", line 223, in urlopen
    return opener.open(url, data, timeout)
  File "/usr/local/lib/python3.6/urllib/request.py", line 532, in open
    response = meth(req, response)
  File "/usr/local/lib/python3.6/urllib/request.py", line 642, in http_response
    'http', request, response, code, msg, hdrs)
  File "/usr/local/lib/python3.6/urllib/request.py", line 570, in error
    return self._call_chain(*args)
  File "/usr/local/lib/python3.6/urllib/request.py", line 504, in _call_chain
    result = func(*args)
  File "/usr/local/lib/python3.6/urllib/request.py", line 650, in http_error_default
    raise HTTPError(req.full_url, code, msg, hdrs, fp)
urllib.error.HTTPError: HTTP Error 404: Not Found
ERROR:root:http://in.reuters.com//ar.reuters.com
Traceback (most recent call last):
  File "web_search3.py", line 33, in searchUrl
    urlContent = urllib.request.urlopen(req).read()
  File "/usr/local/lib/python3.6/urllib/request.py", line 223, in urlopen
    return opener.open(url, data, timeout)
  File "/usr/local/lib/python3.6/urllib/request.py", line 532, in open
    response = meth(req, response)
  File "/usr/local/lib/python3.6/urllib/request.py", line 642, in http_response
    'http', request, response, code, msg, hdrs)
  File "/usr/local/lib/python3.6/urllib/request.py", line 570, in error
    return self._call_chain(*args)
  File "/usr/local/lib/python3.6/urllib/request.py", line 504, in _call_chain
    result = func(*args)
  File "/usr/local/lib/python3.6/urllib/request.py", line 650, in http_error_default
    raise HTTPError(req.full_url, code, msg, hdrs, fp)
urllib.error.HTTPError: HTTP Error 404: Not Found
ERROR:root:http://in.reuters.com//br.reuters.com
Traceback (most recent call last):
  File "web_search3.py", line 33, in searchUrl
    urlContent = urllib.request.urlopen(req).read()
  File "/usr/local/lib/python3.6/urllib/request.py", line 223, in urlopen
    return opener.open(url, data, timeout)
  File "/usr/local/lib/python3.6/urllib/request.py", line 532, in open
    response = meth(req, response)
  File "/usr/local/lib/python3.6/urllib/request.py", line 642, in http_response
    'http', request, response, code, msg, hdrs)
  File "/usr/local/lib/python3.6/urllib/request.py", line 570, in error
    return self._call_chain(*args)
  File "/usr/local/lib/python3.6/urllib/request.py", line 504, in _call_chain
    result = func(*args)
  File "/usr/local/lib/python3.6/urllib/request.py", line 650, in http_error_default
    raise HTTPError(req.full_url, code, msg, hdrs, fp)
urllib.error.HTTPError: HTTP Error 404: Not Found
ERROR:root:http://in.reuters.com//ca.reuters.com
Traceback (most recent call last):
  File "web_search3.py", line 33, in searchUrl
    urlContent = urllib.request.urlopen(req).read()
  File "/usr/local/lib/python3.6/urllib/request.py", line 223, in urlopen
    return opener.open(url, data, timeout)
  File "/usr/local/lib/python3.6/urllib/request.py", line 532, in open
    response = meth(req, response)
  File "/usr/local/lib/python3.6/urllib/request.py", line 642, in http_response
    'http', request, response, code, msg, hdrs)
  File "/usr/local/lib/python3.6/urllib/request.py", line 570, in error
    return self._call_chain(*args)
  File "/usr/local/lib/python3.6/urllib/request.py", line 504, in _call_chain
    result = func(*args)
  File "/usr/local/lib/python3.6/urllib/request.py", line 650, in http_error_default
    raise HTTPError(req.full_url, code, msg, hdrs, fp)
urllib.error.HTTPError: HTTP Error 404: Not Found
ERROR:root:http://in.reuters.com//cn.reuters.com
Traceback (most recent call last):
  File "web_search3.py", line 33, in searchUrl
    urlContent = urllib.request.urlopen(req).read()
  File "/usr/local/lib/python3.6/urllib/request.py", line 223, in urlopen
    return opener.open(url, data, timeout)
  File "/usr/local/lib/python3.6/urllib/request.py", line 532, in open
    response = meth(req, response)
  File "/usr/local/lib/python3.6/urllib/request.py", line 642, in http_response
    'http', request, response, code, msg, hdrs)
  File "/usr/local/lib/python3.6/urllib/request.py", line 570, in error
    return self._call_chain(*args)
  File "/usr/local/lib/python3.6/urllib/request.py", line 504, in _call_chain
    result = func(*args)
  File "/usr/local/lib/python3.6/urllib/request.py", line 650, in http_error_default
    raise HTTPError(req.full_url, code, msg, hdrs, fp)
urllib.error.HTTPError: HTTP Error 404: Not Found
ERROR:root:http://in.reuters.com//de.reuters.com
Traceback (most recent call last):
  File "web_search3.py", line 33, in searchUrl
    urlContent = urllib.request.urlopen(req).read()
  File "/usr/local/lib/python3.6/urllib/request.py", line 223, in urlopen
    return opener.open(url, data, timeout)
  File "/usr/local/lib/python3.6/urllib/request.py", line 532, in open
    response = meth(req, response)
  File "/usr/local/lib/python3.6/urllib/request.py", line 642, in http_response
    'http', request, response, code, msg, hdrs)
  File "/usr/local/lib/python3.6/urllib/request.py", line 570, in error
    return self._call_chain(*args)
  File "/usr/local/lib/python3.6/urllib/request.py", line 504, in _call_chain
    result = func(*args)
  File "/usr/local/lib/python3.6/urllib/request.py", line 650, in http_error_default
    raise HTTPError(req.full_url, code, msg, hdrs, fp)
urllib.error.HTTPError: HTTP Error 404: Not Found
ERROR:root:http://in.reuters.com//es.reuters.com
Traceback (most recent call last):
  File "web_search3.py", line 33, in searchUrl
    urlContent = urllib.request.urlopen(req).read()
  File "/usr/local/lib/python3.6/urllib/request.py", line 223, in urlopen
    return opener.open(url, data, timeout)
  File "/usr/local/lib/python3.6/urllib/request.py", line 532, in open
    response = meth(req, response)
  File "/usr/local/lib/python3.6/urllib/request.py", line 642, in http_response
    'http', request, response, code, msg, hdrs)
  File "/usr/local/lib/python3.6/urllib/request.py", line 570, in error
    return self._call_chain(*args)
  File "/usr/local/lib/python3.6/urllib/request.py", line 504, in _call_chain
    result = func(*args)
  File "/usr/local/lib/python3.6/urllib/request.py", line 650, in http_error_default
    raise HTTPError(req.full_url, code, msg, hdrs, fp)
urllib.error.HTTPError: HTTP Error 404: Not Found
ERROR:root:http://in.reuters.com//fr.reuters.com
Traceback (most recent call last):
  File "web_search3.py", line 33, in searchUrl
    urlContent = urllib.request.urlopen(req).read()
  File "/usr/local/lib/python3.6/urllib/request.py", line 223, in urlopen
    return opener.open(url, data, timeout)
  File "/usr/local/lib/python3.6/urllib/request.py", line 532, in open
    response = meth(req, response)
  File "/usr/local/lib/python3.6/urllib/request.py", line 642, in http_response
    'http', request, response, code, msg, hdrs)
  File "/usr/local/lib/python3.6/urllib/request.py", line 570, in error
    return self._call_chain(*args)
  File "/usr/local/lib/python3.6/urllib/request.py", line 504, in _call_chain
    result = func(*args)
  File "/usr/local/lib/python3.6/urllib/request.py", line 650, in http_error_default
    raise HTTPError(req.full_url, code, msg, hdrs, fp)
urllib.error.HTTPError: HTTP Error 404: Not Found
ERROR:root:http://in.reuters.com//in.reuters.com
Traceback (most recent call last):
  File "web_search3.py", line 33, in searchUrl
    urlContent = urllib.request.urlopen(req).read()
  File "/usr/local/lib/python3.6/urllib/request.py", line 223, in urlopen
    return opener.open(url, data, timeout)
  File "/usr/local/lib/python3.6/urllib/request.py", line 532, in open
    response = meth(req, response)
  File "/usr/local/lib/python3.6/urllib/request.py", line 642, in http_response
    'http', request, response, code, msg, hdrs)
  File "/usr/local/lib/python3.6/urllib/request.py", line 570, in error
    return self._call_chain(*args)
  File "/usr/local/lib/python3.6/urllib/request.py", line 504, in _call_chain
    result = func(*args)
  File "/usr/local/lib/python3.6/urllib/request.py", line 650, in http_error_default
    raise HTTPError(req.full_url, code, msg, hdrs, fp)
urllib.error.HTTPError: HTTP Error 404: Not Found
ERROR:root:http://in.reuters.com//it.reuters.com
Traceback (most recent call last):
  File "web_search3.py", line 33, in searchUrl
    urlContent = urllib.request.urlopen(req).read()
  File "/usr/local/lib/python3.6/urllib/request.py", line 223, in urlopen
    return opener.open(url, data, timeout)
  File "/usr/local/lib/python3.6/urllib/request.py", line 532, in open
    response = meth(req, response)
  File "/usr/local/lib/python3.6/urllib/request.py", line 642, in http_response
    'http', request, response, code, msg, hdrs)
  File "/usr/local/lib/python3.6/urllib/request.py", line 570, in error
    return self._call_chain(*args)
  File "/usr/local/lib/python3.6/urllib/request.py", line 504, in _call_chain
    result = func(*args)
  File "/usr/local/lib/python3.6/urllib/request.py", line 650, in http_error_default
    raise HTTPError(req.full_url, code, msg, hdrs, fp)
urllib.error.HTTPError: HTTP Error 404: Not Found
ERROR:root:http://in.reuters.com//jp.reuters.com
Traceback (most recent call last):
  File "web_search3.py", line 33, in searchUrl
    urlContent = urllib.request.urlopen(req).read()
  File "/usr/local/lib/python3.6/urllib/request.py", line 223, in urlopen
    return opener.open(url, data, timeout)
  File "/usr/local/lib/python3.6/urllib/request.py", line 532, in open
    response = meth(req, response)
  File "/usr/local/lib/python3.6/urllib/request.py", line 642, in http_response
    'http', request, response, code, msg, hdrs)
  File "/usr/local/lib/python3.6/urllib/request.py", line 570, in error
    return self._call_chain(*args)
  File "/usr/local/lib/python3.6/urllib/request.py", line 504, in _call_chain
    result = func(*args)
  File "/usr/local/lib/python3.6/urllib/request.py", line 650, in http_error_default
    raise HTTPError(req.full_url, code, msg, hdrs, fp)
urllib.error.HTTPError: HTTP Error 404: Not Found
ERROR:root:http://in.reuters.com//mx.reuters.com
Traceback (most recent call last):
  File "web_search3.py", line 33, in searchUrl
    urlContent = urllib.request.urlopen(req).read()
  File "/usr/local/lib/python3.6/urllib/request.py", line 223, in urlopen
    return opener.open(url, data, timeout)
  File "/usr/local/lib/python3.6/urllib/request.py", line 532, in open
    response = meth(req, response)
  File "/usr/local/lib/python3.6/urllib/request.py", line 642, in http_response
    'http', request, response, code, msg, hdrs)
  File "/usr/local/lib/python3.6/urllib/request.py", line 570, in error
    return self._call_chain(*args)
  File "/usr/local/lib/python3.6/urllib/request.py", line 504, in _call_chain
    result = func(*args)
  File "/usr/local/lib/python3.6/urllib/request.py", line 650, in http_error_default
    raise HTTPError(req.full_url, code, msg, hdrs, fp)
urllib.error.HTTPError: HTTP Error 404: Not Found
ERROR:root:http://in.reuters.com//ru.reuters.com
Traceback (most recent call last):
  File "web_search3.py", line 33, in searchUrl
    urlContent = urllib.request.urlopen(req).read()
  File "/usr/local/lib/python3.6/urllib/request.py", line 223, in urlopen
    return opener.open(url, data, timeout)
  File "/usr/local/lib/python3.6/urllib/request.py", line 532, in open
    response = meth(req, response)
  File "/usr/local/lib/python3.6/urllib/request.py", line 642, in http_response
    'http', request, response, code, msg, hdrs)
  File "/usr/local/lib/python3.6/urllib/request.py", line 570, in error
    return self._call_chain(*args)
  File "/usr/local/lib/python3.6/urllib/request.py", line 504, in _call_chain
    result = func(*args)
  File "/usr/local/lib/python3.6/urllib/request.py", line 650, in http_error_default
    raise HTTPError(req.full_url, code, msg, hdrs, fp)
urllib.error.HTTPError: HTTP Error 404: Not Found
ERROR:root:http://in.reuters.com//uk.reuters.com
Traceback (most recent call last):
  File "web_search3.py", line 33, in searchUrl
    urlContent = urllib.request.urlopen(req).read()
  File "/usr/local/lib/python3.6/urllib/request.py", line 223, in urlopen
    return opener.open(url, data, timeout)
  File "/usr/local/lib/python3.6/urllib/request.py", line 532, in open
    response = meth(req, response)
  File "/usr/local/lib/python3.6/urllib/request.py", line 642, in http_response
    'http', request, response, code, msg, hdrs)
  File "/usr/local/lib/python3.6/urllib/request.py", line 570, in error
    return self._call_chain(*args)
  File "/usr/local/lib/python3.6/urllib/request.py", line 504, in _call_chain
    result = func(*args)
  File "/usr/local/lib/python3.6/urllib/request.py", line 650, in http_error_default
    raise HTTPError(req.full_url, code, msg, hdrs, fp)
urllib.error.HTTPError: HTTP Error 404: Not Found
ERROR:root:http://in.reuters.com//www.reuters.com
Traceback (most recent call last):
  File "web_search3.py", line 33, in searchUrl
    urlContent = urllib.request.urlopen(req).read()
  File "/usr/local/lib/python3.6/urllib/request.py", line 223, in urlopen
    return opener.open(url, data, timeout)
  File "/usr/local/lib/python3.6/urllib/request.py", line 532, in open
    response = meth(req, response)
  File "/usr/local/lib/python3.6/urllib/request.py", line 642, in http_response
    'http', request, response, code, msg, hdrs)
  File "/usr/local/lib/python3.6/urllib/request.py", line 570, in error
    return self._call_chain(*args)
  File "/usr/local/lib/python3.6/urllib/request.py", line 504, in _call_chain
    result = func(*args)
  File "/usr/local/lib/python3.6/urllib/request.py", line 650, in http_error_default
    raise HTTPError(req.full_url, code, msg, hdrs, fp)
urllib.error.HTTPError: HTTP Error 404: Not Found
ERROR:root:http://in.reuters.com//in.reuters.com/finance/economy
Traceback (most recent call last):
  File "web_search3.py", line 33, in searchUrl
    urlContent = urllib.request.urlopen(req).read()
  File "/usr/local/lib/python3.6/urllib/request.py", line 223, in urlopen
    return opener.open(url, data, timeout)
  File "/usr/local/lib/python3.6/urllib/request.py", line 532, in open
    response = meth(req, response)
  File "/usr/local/lib/python3.6/urllib/request.py", line 642, in http_response
    'http', request, response, code, msg, hdrs)
  File "/usr/local/lib/python3.6/urllib/request.py", line 570, in error
    return self._call_chain(*args)
  File "/usr/local/lib/python3.6/urllib/request.py", line 504, in _call_chain
    result = func(*args)
  File "/usr/local/lib/python3.6/urllib/request.py", line 650, in http_error_default
    raise HTTPError(req.full_url, code, msg, hdrs, fp)
urllib.error.HTTPError: HTTP Error 404: Not Found
ERROR:root:http://in.reuters.com//in.reuters.com/news/entertainment/bollywood
Traceback (most recent call last):
  File "web_search3.py", line 33, in searchUrl
    urlContent = urllib.request.urlopen(req).read()
  File "/usr/local/lib/python3.6/urllib/request.py", line 223, in urlopen
    return opener.open(url, data, timeout)
  File "/usr/local/lib/python3.6/urllib/request.py", line 532, in open
    response = meth(req, response)
  File "/usr/local/lib/python3.6/urllib/request.py", line 642, in http_response
    'http', request, response, code, msg, hdrs)
  File "/usr/local/lib/python3.6/urllib/request.py", line 570, in error
    return self._call_chain(*args)
  File "/usr/local/lib/python3.6/urllib/request.py", line 504, in _call_chain
    result = func(*args)
  File "/usr/local/lib/python3.6/urllib/request.py", line 650, in http_error_default
    raise HTTPError(req.full_url, code, msg, hdrs, fp)
urllib.error.HTTPError: HTTP Error 404: Not Found
ERROR:root:http://in.reuters.com//twitter.com/ReutersIndia
Traceback (most recent call last):
  File "web_search3.py", line 33, in searchUrl
    urlContent = urllib.request.urlopen(req).read()
  File "/usr/local/lib/python3.6/urllib/request.py", line 223, in urlopen
    return opener.open(url, data, timeout)
  File "/usr/local/lib/python3.6/urllib/request.py", line 532, in open
    response = meth(req, response)
  File "/usr/local/lib/python3.6/urllib/request.py", line 642, in http_response
    'http', request, response, code, msg, hdrs)
  File "/usr/local/lib/python3.6/urllib/request.py", line 570, in error
    return self._call_chain(*args)
  File "/usr/local/lib/python3.6/urllib/request.py", line 504, in _call_chain
    result = func(*args)
  File "/usr/local/lib/python3.6/urllib/request.py", line 650, in http_error_default
    raise HTTPError(req.full_url, code, msg, hdrs, fp)
urllib.error.HTTPError: HTTP Error 404: Not Found
ERROR:root:http://in.reuters.com//www.facebook.com/india.reuters/
Traceback (most recent call last):
  File "web_search3.py", line 33, in searchUrl
    urlContent = urllib.request.urlopen(req).read()
  File "/usr/local/lib/python3.6/urllib/request.py", line 223, in urlopen
    return opener.open(url, data, timeout)
  File "/usr/local/lib/python3.6/urllib/request.py", line 532, in open
    response = meth(req, response)
  File "/usr/local/lib/python3.6/urllib/request.py", line 642, in http_response
    'http', request, response, code, msg, hdrs)
  File "/usr/local/lib/python3.6/urllib/request.py", line 564, in error
    result = self._call_chain(*args)
  File "/usr/local/lib/python3.6/urllib/request.py", line 504, in _call_chain
    result = func(*args)
  File "/usr/local/lib/python3.6/urllib/request.py", line 756, in http_error_302
    return self.parent.open(new, timeout=req.timeout)
  File "/usr/local/lib/python3.6/urllib/request.py", line 532, in open
    response = meth(req, response)
  File "/usr/local/lib/python3.6/urllib/request.py", line 642, in http_response
    'http', request, response, code, msg, hdrs)
  File "/usr/local/lib/python3.6/urllib/request.py", line 570, in error
    return self._call_chain(*args)
  File "/usr/local/lib/python3.6/urllib/request.py", line 504, in _call_chain
    result = func(*args)
  File "/usr/local/lib/python3.6/urllib/request.py", line 650, in http_error_default
    raise HTTPError(req.full_url, code, msg, hdrs, fp)
urllib.error.HTTPError: HTTP Error 404: Not Found
ERROR:root:http://in.reuters.com//in.reuters.com/tools/rss
Traceback (most recent call last):
  File "web_search3.py", line 33, in searchUrl
    urlContent = urllib.request.urlopen(req).read()
  File "/usr/local/lib/python3.6/urllib/request.py", line 223, in urlopen
    return opener.open(url, data, timeout)
  File "/usr/local/lib/python3.6/urllib/request.py", line 532, in open
    response = meth(req, response)
  File "/usr/local/lib/python3.6/urllib/request.py", line 642, in http_response
    'http', request, response, code, msg, hdrs)
  File "/usr/local/lib/python3.6/urllib/request.py", line 570, in error
    return self._call_chain(*args)
  File "/usr/local/lib/python3.6/urllib/request.py", line 504, in _call_chain
    result = func(*args)
  File "/usr/local/lib/python3.6/urllib/request.py", line 650, in http_error_default
    raise HTTPError(req.full_url, code, msg, hdrs, fp)
urllib.error.HTTPError: HTTP Error 404: Not Found
ERROR:root:http://in.reuters.com//www.linkedin.com/company/thomson-reuters_1400
Traceback (most recent call last):
  File "web_search3.py", line 33, in searchUrl
    urlContent = urllib.request.urlopen(req).read()
  File "/usr/local/lib/python3.6/urllib/request.py", line 223, in urlopen
    return opener.open(url, data, timeout)
  File "/usr/local/lib/python3.6/urllib/request.py", line 532, in open
    response = meth(req, response)
  File "/usr/local/lib/python3.6/urllib/request.py", line 642, in http_response
    'http', request, response, code, msg, hdrs)
  File "/usr/local/lib/python3.6/urllib/request.py", line 570, in error
    return self._call_chain(*args)
  File "/usr/local/lib/python3.6/urllib/request.py", line 504, in _call_chain
    result = func(*args)
  File "/usr/local/lib/python3.6/urllib/request.py", line 650, in http_error_default
    raise HTTPError(req.full_url, code, msg, hdrs, fp)
urllib.error.HTTPError: HTTP Error 404: Not Found
ERROR:root:http://in.reuters.com//newslink.in.reuters.com/join/subscribe
Traceback (most recent call last):
  File "web_search3.py", line 33, in searchUrl
    urlContent = urllib.request.urlopen(req).read()
  File "/usr/local/lib/python3.6/urllib/request.py", line 223, in urlopen
    return opener.open(url, data, timeout)
  File "/usr/local/lib/python3.6/urllib/request.py", line 532, in open
    response = meth(req, response)
  File "/usr/local/lib/python3.6/urllib/request.py", line 642, in http_response
    'http', request, response, code, msg, hdrs)
  File "/usr/local/lib/python3.6/urllib/request.py", line 570, in error
    return self._call_chain(*args)
  File "/usr/local/lib/python3.6/urllib/request.py", line 504, in _call_chain
    result = func(*args)
  File "/usr/local/lib/python3.6/urllib/request.py", line 650, in http_error_default
    raise HTTPError(req.full_url, code, msg, hdrs, fp)
urllib.error.HTTPError: HTTP Error 404: Not Found
ERROR:root:http://in.reuters.com//in.reuters.com/tools/mobile
Traceback (most recent call last):
  File "web_search3.py", line 33, in searchUrl
    urlContent = urllib.request.urlopen(req).read()
  File "/usr/local/lib/python3.6/urllib/request.py", line 223, in urlopen
    return opener.open(url, data, timeout)
  File "/usr/local/lib/python3.6/urllib/request.py", line 532, in open
    response = meth(req, response)
  File "/usr/local/lib/python3.6/urllib/request.py", line 642, in http_response
    'http', request, response, code, msg, hdrs)
  File "/usr/local/lib/python3.6/urllib/request.py", line 570, in error
    return self._call_chain(*args)
  File "/usr/local/lib/python3.6/urllib/request.py", line 504, in _call_chain
    result = func(*args)
  File "/usr/local/lib/python3.6/urllib/request.py", line 650, in http_error_default
    raise HTTPError(req.full_url, code, msg, hdrs, fp)
urllib.error.HTTPError: HTTP Error 404: Not Found
ERROR:root:http://in.reuters.com//plus.reuters.com/en.html 
Traceback (most recent call last):
  File "web_search3.py", line 33, in searchUrl
    urlContent = urllib.request.urlopen(req).read()
  File "/usr/local/lib/python3.6/urllib/request.py", line 223, in urlopen
    return opener.open(url, data, timeout)
  File "/usr/local/lib/python3.6/urllib/request.py", line 532, in open
    response = meth(req, response)
  File "/usr/local/lib/python3.6/urllib/request.py", line 642, in http_response
    'http', request, response, code, msg, hdrs)
  File "/usr/local/lib/python3.6/urllib/request.py", line 570, in error
    return self._call_chain(*args)
  File "/usr/local/lib/python3.6/urllib/request.py", line 504, in _call_chain
    result = func(*args)
  File "/usr/local/lib/python3.6/urllib/request.py", line 650, in http_error_default
    raise HTTPError(req.full_url, code, msg, hdrs, fp)
urllib.error.HTTPError: HTTP Error 404: Not Found
ERROR:root:http://in.reuters.com//agency.reuters.com
Traceback (most recent call last):
  File "web_search3.py", line 33, in searchUrl
    urlContent = urllib.request.urlopen(req).read()
  File "/usr/local/lib/python3.6/urllib/request.py", line 223, in urlopen
    return opener.open(url, data, timeout)
  File "/usr/local/lib/python3.6/urllib/request.py", line 532, in open
    response = meth(req, response)
  File "/usr/local/lib/python3.6/urllib/request.py", line 642, in http_response
    'http', request, response, code, msg, hdrs)
  File "/usr/local/lib/python3.6/urllib/request.py", line 570, in error
    return self._call_chain(*args)
  File "/usr/local/lib/python3.6/urllib/request.py", line 504, in _call_chain
    result = func(*args)
  File "/usr/local/lib/python3.6/urllib/request.py", line 650, in http_error_default
    raise HTTPError(req.full_url, code, msg, hdrs, fp)
urllib.error.HTTPError: HTTP Error 404: Not Found
ERROR:root:http://in.reuters.com//agency.reuters.com/en/platforms-delivery/reuters-brand-attribution-guidelines.html
Traceback (most recent call last):
  File "web_search3.py", line 33, in searchUrl
    urlContent = urllib.request.urlopen(req).read()
  File "/usr/local/lib/python3.6/urllib/request.py", line 223, in urlopen
    return opener.open(url, data, timeout)
  File "/usr/local/lib/python3.6/urllib/request.py", line 532, in open
    response = meth(req, response)
  File "/usr/local/lib/python3.6/urllib/request.py", line 642, in http_response
    'http', request, response, code, msg, hdrs)
  File "/usr/local/lib/python3.6/urllib/request.py", line 570, in error
    return self._call_chain(*args)
  File "/usr/local/lib/python3.6/urllib/request.py", line 504, in _call_chain
    result = func(*args)
  File "/usr/local/lib/python3.6/urllib/request.py", line 650, in http_error_default
    raise HTTPError(req.full_url, code, msg, hdrs, fp)
urllib.error.HTTPError: HTTP Error 404: Not Found
ERROR:root:http://in.reuters.com//thomsonreuters.com/en/careers.html
Traceback (most recent call last):
  File "web_search3.py", line 33, in searchUrl
    urlContent = urllib.request.urlopen(req).read()
  File "/usr/local/lib/python3.6/urllib/request.py", line 223, in urlopen
    return opener.open(url, data, timeout)
  File "/usr/local/lib/python3.6/urllib/request.py", line 532, in open
    response = meth(req, response)
  File "/usr/local/lib/python3.6/urllib/request.py", line 642, in http_response
    'http', request, response, code, msg, hdrs)
  File "/usr/local/lib/python3.6/urllib/request.py", line 570, in error
    return self._call_chain(*args)
  File "/usr/local/lib/python3.6/urllib/request.py", line 504, in _call_chain
    result = func(*args)
  File "/usr/local/lib/python3.6/urllib/request.py", line 650, in http_error_default
    raise HTTPError(req.full_url, code, msg, hdrs, fp)
urllib.error.HTTPError: HTTP Error 404: Not Found
ERROR:root:http://in.reuters.com//thomsonreuters.com/
Traceback (most recent call last):
  File "web_search3.py", line 33, in searchUrl
    urlContent = urllib.request.urlopen(req).read()
  File "/usr/local/lib/python3.6/urllib/request.py", line 223, in urlopen
    return opener.open(url, data, timeout)
  File "/usr/local/lib/python3.6/urllib/request.py", line 532, in open
    response = meth(req, response)
  File "/usr/local/lib/python3.6/urllib/request.py", line 642, in http_response
    'http', request, response, code, msg, hdrs)
  File "/usr/local/lib/python3.6/urllib/request.py", line 564, in error
    result = self._call_chain(*args)
  File "/usr/local/lib/python3.6/urllib/request.py", line 504, in _call_chain
    result = func(*args)
  File "/usr/local/lib/python3.6/urllib/request.py", line 756, in http_error_302
    return self.parent.open(new, timeout=req.timeout)
  File "/usr/local/lib/python3.6/urllib/request.py", line 532, in open
    response = meth(req, response)
  File "/usr/local/lib/python3.6/urllib/request.py", line 642, in http_response
    'http', request, response, code, msg, hdrs)
  File "/usr/local/lib/python3.6/urllib/request.py", line 570, in error
    return self._call_chain(*args)
  File "/usr/local/lib/python3.6/urllib/request.py", line 504, in _call_chain
    result = func(*args)
  File "/usr/local/lib/python3.6/urllib/request.py", line 650, in http_error_default
    raise HTTPError(req.full_url, code, msg, hdrs, fp)
urllib.error.HTTPError: HTTP Error 404: Not Found
ERROR:root:http://in.reuters.com//financial.thomsonreuters.com/en/products/tools-applications/trading-investment-tools/eikon-trading-software.html
Traceback (most recent call last):
  File "web_search3.py", line 33, in searchUrl
    urlContent = urllib.request.urlopen(req).read()
  File "/usr/local/lib/python3.6/urllib/request.py", line 223, in urlopen
    return opener.open(url, data, timeout)
  File "/usr/local/lib/python3.6/urllib/request.py", line 532, in open
    response = meth(req, response)
  File "/usr/local/lib/python3.6/urllib/request.py", line 642, in http_response
    'http', request, response, code, msg, hdrs)
  File "/usr/local/lib/python3.6/urllib/request.py", line 570, in error
    return self._call_chain(*args)
  File "/usr/local/lib/python3.6/urllib/request.py", line 504, in _call_chain
    result = func(*args)
  File "/usr/local/lib/python3.6/urllib/request.py", line 650, in http_error_default
    raise HTTPError(req.full_url, code, msg, hdrs, fp)
urllib.error.HTTPError: HTTP Error 404: Not Found
ERROR:root:http://in.reuters.com//financial.thomsonreuters.com/en/products/infrastructure/trading-infrastructure/elektron-enterprise-data-management.html
Traceback (most recent call last):
  File "web_search3.py", line 33, in searchUrl
    urlContent = urllib.request.urlopen(req).read()
  File "/usr/local/lib/python3.6/urllib/request.py", line 223, in urlopen
    return opener.open(url, data, timeout)
  File "/usr/local/lib/python3.6/urllib/request.py", line 532, in open
    response = meth(req, response)
  File "/usr/local/lib/python3.6/urllib/request.py", line 642, in http_response
    'http', request, response, code, msg, hdrs)
  File "/usr/local/lib/python3.6/urllib/request.py", line 570, in error
    return self._call_chain(*args)
  File "/usr/local/lib/python3.6/urllib/request.py", line 504, in _call_chain
    result = func(*args)
  File "/usr/local/lib/python3.6/urllib/request.py", line 650, in http_error_default
    raise HTTPError(req.full_url, code, msg, hdrs, fp)
urllib.error.HTTPError: HTTP Error 404: Not Found
ERROR:root:http://in.reuters.com//risk.thomsonreuters.com/products/world-check
Traceback (most recent call last):
  File "web_search3.py", line 33, in searchUrl
    urlContent = urllib.request.urlopen(req).read()
  File "/usr/local/lib/python3.6/urllib/request.py", line 223, in urlopen
    return opener.open(url, data, timeout)
  File "/usr/local/lib/python3.6/urllib/request.py", line 532, in open
    response = meth(req, response)
  File "/usr/local/lib/python3.6/urllib/request.py", line 642, in http_response
    'http', request, response, code, msg, hdrs)
  File "/usr/local/lib/python3.6/urllib/request.py", line 570, in error
    return self._call_chain(*args)
  File "/usr/local/lib/python3.6/urllib/request.py", line 504, in _call_chain
    result = func(*args)
  File "/usr/local/lib/python3.6/urllib/request.py", line 650, in http_error_default
    raise HTTPError(req.full_url, code, msg, hdrs, fp)
urllib.error.HTTPError: HTTP Error 404: Not Found
ERROR:root:http://in.reuters.com//legalsolutions.thomsonreuters.com/law-products/westlaw-legal-research/
Traceback (most recent call last):
  File "web_search3.py", line 33, in searchUrl
    urlContent = urllib.request.urlopen(req).read()
  File "/usr/local/lib/python3.6/urllib/request.py", line 223, in urlopen
    return opener.open(url, data, timeout)
  File "/usr/local/lib/python3.6/urllib/request.py", line 532, in open
    response = meth(req, response)
  File "/usr/local/lib/python3.6/urllib/request.py", line 642, in http_response
    'http', request, response, code, msg, hdrs)
  File "/usr/local/lib/python3.6/urllib/request.py", line 564, in error
    result = self._call_chain(*args)
  File "/usr/local/lib/python3.6/urllib/request.py", line 504, in _call_chain
    result = func(*args)
  File "/usr/local/lib/python3.6/urllib/request.py", line 756, in http_error_302
    return self.parent.open(new, timeout=req.timeout)
  File "/usr/local/lib/python3.6/urllib/request.py", line 532, in open
    response = meth(req, response)
  File "/usr/local/lib/python3.6/urllib/request.py", line 642, in http_response
    'http', request, response, code, msg, hdrs)
  File "/usr/local/lib/python3.6/urllib/request.py", line 570, in error
    return self._call_chain(*args)
  File "/usr/local/lib/python3.6/urllib/request.py", line 504, in _call_chain
    result = func(*args)
  File "/usr/local/lib/python3.6/urllib/request.py", line 650, in http_error_default
    raise HTTPError(req.full_url, code, msg, hdrs, fp)
urllib.error.HTTPError: HTTP Error 404: Not Found
ERROR:root:http://in.reuters.com//tax.thomsonreuters.com/products/brands/onesource/
Traceback (most recent call last):
  File "web_search3.py", line 33, in searchUrl
    urlContent = urllib.request.urlopen(req).read()
  File "/usr/local/lib/python3.6/urllib/request.py", line 223, in urlopen
    return opener.open(url, data, timeout)
  File "/usr/local/lib/python3.6/urllib/request.py", line 532, in open
    response = meth(req, response)
  File "/usr/local/lib/python3.6/urllib/request.py", line 642, in http_response
    'http', request, response, code, msg, hdrs)
  File "/usr/local/lib/python3.6/urllib/request.py", line 564, in error
    result = self._call_chain(*args)
  File "/usr/local/lib/python3.6/urllib/request.py", line 504, in _call_chain
    result = func(*args)
  File "/usr/local/lib/python3.6/urllib/request.py", line 756, in http_error_302
    return self.parent.open(new, timeout=req.timeout)
  File "/usr/local/lib/python3.6/urllib/request.py", line 532, in open
    response = meth(req, response)
  File "/usr/local/lib/python3.6/urllib/request.py", line 642, in http_response
    'http', request, response, code, msg, hdrs)
  File "/usr/local/lib/python3.6/urllib/request.py", line 570, in error
    return self._call_chain(*args)
  File "/usr/local/lib/python3.6/urllib/request.py", line 504, in _call_chain
    result = func(*args)
  File "/usr/local/lib/python3.6/urllib/request.py", line 650, in http_error_default
    raise HTTPError(req.full_url, code, msg, hdrs, fp)
urllib.error.HTTPError: HTTP Error 404: Not Found
ERROR:root:http://in.reuters.com//tax.thomsonreuters.com/products/brands/checkpoint/
Traceback (most recent call last):
  File "web_search3.py", line 33, in searchUrl
    urlContent = urllib.request.urlopen(req).read()
  File "/usr/local/lib/python3.6/urllib/request.py", line 223, in urlopen
    return opener.open(url, data, timeout)
  File "/usr/local/lib/python3.6/urllib/request.py", line 532, in open
    response = meth(req, response)
  File "/usr/local/lib/python3.6/urllib/request.py", line 642, in http_response
    'http', request, response, code, msg, hdrs)
  File "/usr/local/lib/python3.6/urllib/request.py", line 564, in error
    result = self._call_chain(*args)
  File "/usr/local/lib/python3.6/urllib/request.py", line 504, in _call_chain
    result = func(*args)
  File "/usr/local/lib/python3.6/urllib/request.py", line 756, in http_error_302
    return self.parent.open(new, timeout=req.timeout)
  File "/usr/local/lib/python3.6/urllib/request.py", line 532, in open
    response = meth(req, response)
  File "/usr/local/lib/python3.6/urllib/request.py", line 642, in http_response
    'http', request, response, code, msg, hdrs)
  File "/usr/local/lib/python3.6/urllib/request.py", line 570, in error
    return self._call_chain(*args)
  File "/usr/local/lib/python3.6/urllib/request.py", line 504, in _call_chain
    result = func(*args)
  File "/usr/local/lib/python3.6/urllib/request.py", line 650, in http_error_default
    raise HTTPError(req.full_url, code, msg, hdrs, fp)
urllib.error.HTTPError: HTTP Error 404: Not Found
ERROR:root:http://in.reuters.com//reuters.zendesk.com/
Traceback (most recent call last):
  File "web_search3.py", line 33, in searchUrl
    urlContent = urllib.request.urlopen(req).read()
  File "/usr/local/lib/python3.6/urllib/request.py", line 223, in urlopen
    return opener.open(url, data, timeout)
  File "/usr/local/lib/python3.6/urllib/request.py", line 532, in open
    response = meth(req, response)
  File "/usr/local/lib/python3.6/urllib/request.py", line 642, in http_response
    'http', request, response, code, msg, hdrs)
  File "/usr/local/lib/python3.6/urllib/request.py", line 564, in error
    result = self._call_chain(*args)
  File "/usr/local/lib/python3.6/urllib/request.py", line 504, in _call_chain
    result = func(*args)
  File "/usr/local/lib/python3.6/urllib/request.py", line 756, in http_error_302
    return self.parent.open(new, timeout=req.timeout)
  File "/usr/local/lib/python3.6/urllib/request.py", line 532, in open
    response = meth(req, response)
  File "/usr/local/lib/python3.6/urllib/request.py", line 642, in http_response
    'http', request, response, code, msg, hdrs)
  File "/usr/local/lib/python3.6/urllib/request.py", line 570, in error
    return self._call_chain(*args)
  File "/usr/local/lib/python3.6/urllib/request.py", line 504, in _call_chain
    result = func(*args)
  File "/usr/local/lib/python3.6/urllib/request.py", line 650, in http_error_default
    raise HTTPError(req.full_url, code, msg, hdrs, fp)
urllib.error.HTTPError: HTTP Error 404: Not Found
ERROR:root:http://in.reuters.com//info.evidon.com/pub_info/15802
Traceback (most recent call last):
  File "web_search3.py", line 33, in searchUrl
    urlContent = urllib.request.urlopen(req).read()
  File "/usr/local/lib/python3.6/urllib/request.py", line 223, in urlopen
    return opener.open(url, data, timeout)
  File "/usr/local/lib/python3.6/urllib/request.py", line 532, in open
    response = meth(req, response)
  File "/usr/local/lib/python3.6/urllib/request.py", line 642, in http_response
    'http', request, response, code, msg, hdrs)
  File "/usr/local/lib/python3.6/urllib/request.py", line 570, in error
    return self._call_chain(*args)
  File "/usr/local/lib/python3.6/urllib/request.py", line 504, in _call_chain
    result = func(*args)
  File "/usr/local/lib/python3.6/urllib/request.py", line 650, in http_error_default
    raise HTTPError(req.full_url, code, msg, hdrs, fp)
urllib.error.HTTPError: HTTP Error 404: Not Found
ERROR:root:http://swarajyamag.com/javascript:void(0)
Traceback (most recent call last):
  File "web_search3.py", line 33, in searchUrl
    urlContent = urllib.request.urlopen(req).read()
  File "/usr/local/lib/python3.6/urllib/request.py", line 223, in urlopen
    return opener.open(url, data, timeout)
  File "/usr/local/lib/python3.6/urllib/request.py", line 532, in open
    response = meth(req, response)
  File "/usr/local/lib/python3.6/urllib/request.py", line 642, in http_response
    'http', request, response, code, msg, hdrs)
  File "/usr/local/lib/python3.6/urllib/request.py", line 564, in error
    result = self._call_chain(*args)
  File "/usr/local/lib/python3.6/urllib/request.py", line 504, in _call_chain
    result = func(*args)
  File "/usr/local/lib/python3.6/urllib/request.py", line 756, in http_error_302
    return self.parent.open(new, timeout=req.timeout)
  File "/usr/local/lib/python3.6/urllib/request.py", line 532, in open
    response = meth(req, response)
  File "/usr/local/lib/python3.6/urllib/request.py", line 642, in http_response
    'http', request, response, code, msg, hdrs)
  File "/usr/local/lib/python3.6/urllib/request.py", line 570, in error
    return self._call_chain(*args)
  File "/usr/local/lib/python3.6/urllib/request.py", line 504, in _call_chain
    result = func(*args)
  File "/usr/local/lib/python3.6/urllib/request.py", line 650, in http_error_default
    raise HTTPError(req.full_url, code, msg, hdrs, fp)
urllib.error.HTTPError: HTTP Error 404: Not Found
ERROR:root:http://swarajyamag.com/mailto:editor@swarajyamag.com
Traceback (most recent call last):
  File "web_search3.py", line 33, in searchUrl
    urlContent = urllib.request.urlopen(req).read()
  File "/usr/local/lib/python3.6/urllib/request.py", line 223, in urlopen
    return opener.open(url, data, timeout)
  File "/usr/local/lib/python3.6/urllib/request.py", line 532, in open
    response = meth(req, response)
  File "/usr/local/lib/python3.6/urllib/request.py", line 642, in http_response
    'http', request, response, code, msg, hdrs)
  File "/usr/local/lib/python3.6/urllib/request.py", line 564, in error
    result = self._call_chain(*args)
  File "/usr/local/lib/python3.6/urllib/request.py", line 504, in _call_chain
    result = func(*args)
  File "/usr/local/lib/python3.6/urllib/request.py", line 756, in http_error_302
    return self.parent.open(new, timeout=req.timeout)
  File "/usr/local/lib/python3.6/urllib/request.py", line 532, in open
    response = meth(req, response)
  File "/usr/local/lib/python3.6/urllib/request.py", line 642, in http_response
    'http', request, response, code, msg, hdrs)
  File "/usr/local/lib/python3.6/urllib/request.py", line 570, in error
    return self._call_chain(*args)
  File "/usr/local/lib/python3.6/urllib/request.py", line 504, in _call_chain
    result = func(*args)
  File "/usr/local/lib/python3.6/urllib/request.py", line 650, in http_error_default
    raise HTTPError(req.full_url, code, msg, hdrs, fp)
urllib.error.HTTPError: HTTP Error 404: Not Found
ERROR:root:http://currentriggers.com/javascript:void(0)
Traceback (most recent call last):
  File "web_search3.py", line 33, in searchUrl
    urlContent = urllib.request.urlopen(req).read()
  File "/usr/local/lib/python3.6/urllib/request.py", line 223, in urlopen
    return opener.open(url, data, timeout)
  File "/usr/local/lib/python3.6/urllib/request.py", line 532, in open
    response = meth(req, response)
  File "/usr/local/lib/python3.6/urllib/request.py", line 642, in http_response
    'http', request, response, code, msg, hdrs)
  File "/usr/local/lib/python3.6/urllib/request.py", line 570, in error
    return self._call_chain(*args)
  File "/usr/local/lib/python3.6/urllib/request.py", line 504, in _call_chain
    result = func(*args)
  File "/usr/local/lib/python3.6/urllib/request.py", line 650, in http_error_default
    raise HTTPError(req.full_url, code, msg, hdrs, fp)
urllib.error.HTTPError: HTTP Error 404: Not Found
ERROR:root:http://currentriggers.com/javascript:void(0)
Traceback (most recent call last):
  File "web_search3.py", line 33, in searchUrl
    urlContent = urllib.request.urlopen(req).read()
  File "/usr/local/lib/python3.6/urllib/request.py", line 223, in urlopen
    return opener.open(url, data, timeout)
  File "/usr/local/lib/python3.6/urllib/request.py", line 532, in open
    response = meth(req, response)
  File "/usr/local/lib/python3.6/urllib/request.py", line 642, in http_response
    'http', request, response, code, msg, hdrs)
  File "/usr/local/lib/python3.6/urllib/request.py", line 570, in error
    return self._call_chain(*args)
  File "/usr/local/lib/python3.6/urllib/request.py", line 504, in _call_chain
    result = func(*args)
  File "/usr/local/lib/python3.6/urllib/request.py", line 650, in http_error_default
    raise HTTPError(req.full_url, code, msg, hdrs, fp)
urllib.error.HTTPError: HTTP Error 404: Not Found
ERROR:root:http://worldhindunews.com/www.nhsf.org.uk
Traceback (most recent call last):
  File "web_search3.py", line 33, in searchUrl
    urlContent = urllib.request.urlopen(req).read()
  File "/usr/local/lib/python3.6/urllib/request.py", line 223, in urlopen
    return opener.open(url, data, timeout)
  File "/usr/local/lib/python3.6/urllib/request.py", line 532, in open
    response = meth(req, response)
  File "/usr/local/lib/python3.6/urllib/request.py", line 642, in http_response
    'http', request, response, code, msg, hdrs)
  File "/usr/local/lib/python3.6/urllib/request.py", line 564, in error
    result = self._call_chain(*args)
  File "/usr/local/lib/python3.6/urllib/request.py", line 504, in _call_chain
    result = func(*args)
  File "/usr/local/lib/python3.6/urllib/request.py", line 756, in http_error_302
    return self.parent.open(new, timeout=req.timeout)
  File "/usr/local/lib/python3.6/urllib/request.py", line 532, in open
    response = meth(req, response)
  File "/usr/local/lib/python3.6/urllib/request.py", line 642, in http_response
    'http', request, response, code, msg, hdrs)
  File "/usr/local/lib/python3.6/urllib/request.py", line 570, in error
    return self._call_chain(*args)
  File "/usr/local/lib/python3.6/urllib/request.py", line 504, in _call_chain
    result = func(*args)
  File "/usr/local/lib/python3.6/urllib/request.py", line 650, in http_error_default
    raise HTTPError(req.full_url, code, msg, hdrs, fp)
urllib.error.HTTPError: HTTP Error 404: Not Found
ERROR:root:http://www.dailyo.in/whatsapp://send
Traceback (most recent call last):
  File "web_search3.py", line 33, in searchUrl
    urlContent = urllib.request.urlopen(req).read()
  File "/usr/local/lib/python3.6/urllib/request.py", line 223, in urlopen
    return opener.open(url, data, timeout)
  File "/usr/local/lib/python3.6/urllib/request.py", line 532, in open
    response = meth(req, response)
  File "/usr/local/lib/python3.6/urllib/request.py", line 642, in http_response
    'http', request, response, code, msg, hdrs)
  File "/usr/local/lib/python3.6/urllib/request.py", line 570, in error
    return self._call_chain(*args)
  File "/usr/local/lib/python3.6/urllib/request.py", line 504, in _call_chain
    result = func(*args)
  File "/usr/local/lib/python3.6/urllib/request.py", line 650, in http_error_default
    raise HTTPError(req.full_url, code, msg, hdrs, fp)
urllib.error.HTTPError: HTTP Error 404: Not Found
ERROR:root:https://hinduexistence.org/2017/07/02/i-was-told-to-be-converted-in-islam-claims-hindu-canteen-operator-in-malaysia/
Traceback (most recent call last):
  File "web_search3.py", line 33, in searchUrl
    urlContent = urllib.request.urlopen(req).read()
  File "/usr/local/lib/python3.6/urllib/request.py", line 223, in urlopen
    return opener.open(url, data, timeout)
  File "/usr/local/lib/python3.6/urllib/request.py", line 532, in open
    response = meth(req, response)
  File "/usr/local/lib/python3.6/urllib/request.py", line 642, in http_response
    'http', request, response, code, msg, hdrs)
  File "/usr/local/lib/python3.6/urllib/request.py", line 570, in error
    return self._call_chain(*args)
  File "/usr/local/lib/python3.6/urllib/request.py", line 504, in _call_chain
    result = func(*args)
  File "/usr/local/lib/python3.6/urllib/request.py", line 650, in http_error_default
    raise HTTPError(req.full_url, code, msg, hdrs, fp)
urllib.error.HTTPError: HTTP Error 404: Not Found
ERROR:root:https://hinduexistence.org/2017/07/01/dalit-father-and-brother-tied-to-a-tree-and-beaten-up-by-muslims-as-a-dalit-boy-elopes-with-a-muslim-girl/
Traceback (most recent call last):
  File "web_search3.py", line 33, in searchUrl
    urlContent = urllib.request.urlopen(req).read()
  File "/usr/local/lib/python3.6/urllib/request.py", line 223, in urlopen
    return opener.open(url, data, timeout)
  File "/usr/local/lib/python3.6/urllib/request.py", line 532, in open
    response = meth(req, response)
  File "/usr/local/lib/python3.6/urllib/request.py", line 642, in http_response
    'http', request, response, code, msg, hdrs)
  File "/usr/local/lib/python3.6/urllib/request.py", line 570, in error
    return self._call_chain(*args)
  File "/usr/local/lib/python3.6/urllib/request.py", line 504, in _call_chain
    result = func(*args)
  File "/usr/local/lib/python3.6/urllib/request.py", line 650, in http_error_default
    raise HTTPError(req.full_url, code, msg, hdrs, fp)
urllib.error.HTTPError: HTTP Error 404: Not Found
ERROR:root:https://www.hindujagruti.org/javascript:
Traceback (most recent call last):
  File "web_search3.py", line 33, in searchUrl
    urlContent = urllib.request.urlopen(req).read()
  File "/usr/local/lib/python3.6/urllib/request.py", line 223, in urlopen
    return opener.open(url, data, timeout)
  File "/usr/local/lib/python3.6/urllib/request.py", line 532, in open
    response = meth(req, response)
  File "/usr/local/lib/python3.6/urllib/request.py", line 642, in http_response
    'http', request, response, code, msg, hdrs)
  File "/usr/local/lib/python3.6/urllib/request.py", line 570, in error
    return self._call_chain(*args)
  File "/usr/local/lib/python3.6/urllib/request.py", line 504, in _call_chain
    result = func(*args)
  File "/usr/local/lib/python3.6/urllib/request.py", line 650, in http_error_default
    raise HTTPError(req.full_url, code, msg, hdrs, fp)
urllib.error.HTTPError: HTTP Error 404: Not Found
ERROR:root:https://www.hindujagruti.org//www.hindujagruti.org/
Traceback (most recent call last):
  File "web_search3.py", line 33, in searchUrl
    urlContent = urllib.request.urlopen(req).read()
  File "/usr/local/lib/python3.6/urllib/request.py", line 223, in urlopen
    return opener.open(url, data, timeout)
  File "/usr/local/lib/python3.6/urllib/request.py", line 532, in open
    response = meth(req, response)
  File "/usr/local/lib/python3.6/urllib/request.py", line 642, in http_response
    'http', request, response, code, msg, hdrs)
  File "/usr/local/lib/python3.6/urllib/request.py", line 564, in error
    result = self._call_chain(*args)
  File "/usr/local/lib/python3.6/urllib/request.py", line 504, in _call_chain
    result = func(*args)
  File "/usr/local/lib/python3.6/urllib/request.py", line 756, in http_error_302
    return self.parent.open(new, timeout=req.timeout)
  File "/usr/local/lib/python3.6/urllib/request.py", line 532, in open
    response = meth(req, response)
  File "/usr/local/lib/python3.6/urllib/request.py", line 642, in http_response
    'http', request, response, code, msg, hdrs)
  File "/usr/local/lib/python3.6/urllib/request.py", line 570, in error
    return self._call_chain(*args)
  File "/usr/local/lib/python3.6/urllib/request.py", line 504, in _call_chain
    result = func(*args)
  File "/usr/local/lib/python3.6/urllib/request.py", line 650, in http_error_default
    raise HTTPError(req.full_url, code, msg, hdrs, fp)
urllib.error.HTTPError: HTTP Error 404: Not Found
ERROR:root:https://www.hindujagruti.org//www.hindujagruti.org/hindi
Traceback (most recent call last):
  File "web_search3.py", line 33, in searchUrl
    urlContent = urllib.request.urlopen(req).read()
  File "/usr/local/lib/python3.6/urllib/request.py", line 223, in urlopen
    return opener.open(url, data, timeout)
  File "/usr/local/lib/python3.6/urllib/request.py", line 532, in open
    response = meth(req, response)
  File "/usr/local/lib/python3.6/urllib/request.py", line 642, in http_response
    'http', request, response, code, msg, hdrs)
  File "/usr/local/lib/python3.6/urllib/request.py", line 564, in error
    result = self._call_chain(*args)
  File "/usr/local/lib/python3.6/urllib/request.py", line 504, in _call_chain
    result = func(*args)
  File "/usr/local/lib/python3.6/urllib/request.py", line 756, in http_error_302
    return self.parent.open(new, timeout=req.timeout)
  File "/usr/local/lib/python3.6/urllib/request.py", line 532, in open
    response = meth(req, response)
  File "/usr/local/lib/python3.6/urllib/request.py", line 642, in http_response
    'http', request, response, code, msg, hdrs)
  File "/usr/local/lib/python3.6/urllib/request.py", line 570, in error
    return self._call_chain(*args)
  File "/usr/local/lib/python3.6/urllib/request.py", line 504, in _call_chain
    result = func(*args)
  File "/usr/local/lib/python3.6/urllib/request.py", line 650, in http_error_default
    raise HTTPError(req.full_url, code, msg, hdrs, fp)
urllib.error.HTTPError: HTTP Error 404: Not Found
ERROR:root:https://www.hindujagruti.org//www.hindujagruti.org/marathi/
Traceback (most recent call last):
  File "web_search3.py", line 33, in searchUrl
    urlContent = urllib.request.urlopen(req).read()
  File "/usr/local/lib/python3.6/urllib/request.py", line 223, in urlopen
    return opener.open(url, data, timeout)
  File "/usr/local/lib/python3.6/urllib/request.py", line 532, in open
    response = meth(req, response)
  File "/usr/local/lib/python3.6/urllib/request.py", line 642, in http_response
    'http', request, response, code, msg, hdrs)
  File "/usr/local/lib/python3.6/urllib/request.py", line 564, in error
    result = self._call_chain(*args)
  File "/usr/local/lib/python3.6/urllib/request.py", line 504, in _call_chain
    result = func(*args)
  File "/usr/local/lib/python3.6/urllib/request.py", line 756, in http_error_302
    return self.parent.open(new, timeout=req.timeout)
  File "/usr/local/lib/python3.6/urllib/request.py", line 532, in open
    response = meth(req, response)
  File "/usr/local/lib/python3.6/urllib/request.py", line 642, in http_response
    'http', request, response, code, msg, hdrs)
  File "/usr/local/lib/python3.6/urllib/request.py", line 570, in error
    return self._call_chain(*args)
  File "/usr/local/lib/python3.6/urllib/request.py", line 504, in _call_chain
    result = func(*args)
  File "/usr/local/lib/python3.6/urllib/request.py", line 650, in http_error_default
    raise HTTPError(req.full_url, code, msg, hdrs, fp)
urllib.error.HTTPError: HTTP Error 404: Not Found
